Workbook
Name AGENCE_INFRA: REF!$J$2:$J$91
Name CDP_INFRA: REF!$I$2:$I$91
Name COEF_FCI: Recap_FCI!$I$19
Name DOM: Recap_FCI!$D$79
Name FAM_FCI: FAMILLE!$A$2:$A$122
Name IC_INFRA: REF!$H$2:$H$91
Name LOG_FCI: Recap_FCI!$D$77
Name LOT_1: Recap_FCI!$K$9
Name LOT_FCI: Recap_FCI!$K$9:$S$9
Name OFFRES: REF!$K$2:$K$91
Name PV_FCI: Recap_FCI!$F$13
Name RISQ_CHAR: Recap_FCI!$D$78
Name TECHNOLOGIES: REF!$L$2:$L$91
Name TXMO1: Recap_FCI!$E$43
Name TXMO2: Recap_FCI!$E$44
Name TXMO3: Recap_FCI!$E$45
Name TXMO4: Recap_FCI!$E$46
Name TXMO5: Recap_FCI!$E$47
Name TXMO6: Recap_FCI!$E$48
Name TXMO7: Recap_FCI!$E$49
Name TXMO8: Recap_FCI!$E$50

Sheet Page de garde

Sheet Recap_FCI
A2: Client : | C2: EXYTE | F2: N° d'Offre : | G2: [ N° d'offre ] | I2: Date réception AO : | L2: Client Preneur :
A3: Affaire : | C3: KHAZNA ORY01 — Base vie & chantier — Lot courants faibles | F3: Architecte : | G3: Woody SEALE | I3: Date Revue Offre : | L3: Maitrise d'Ouvrage :
A4: Site : | B4: Site : | C4: RD 57 — 77390 Fouju (77) | F4: Ingénieur Affaires: | G4: Woody SEALE | I4: Date Remise Offre : | L4: Aménageur / BET / AMOA :
A5: Adresse: | B5: Adresse: | F5: Agence : | I5: Date Soutenance : | L5: Maitrise d'Œuvre : | M5: Maitrise d'Œuvre :
A6: Techno: | B6: Techno: | C6: VDI / CFA / SSI / GTB | F6: BET : | I6: Date Décision : | L6: Entrepreneur Principal : | M6: Entrepreneur Principal :
A7: Offre : | F7: Date de MES Promise : | I7: Date Début Projet :
A9: RECAPITULATIF | I9: MO | J9: MAT | K9: VDI | L9: CFO | M9: CFA | N9: SSI | O9: CVC | P9: OC | Q9: VR1 | R9: VR2 | S9: VR3
A10: Total des Couts indirects : | F10: =SUM(F51:F79)/2 | G10: Remise achats sur couts directs : | I10: =SUMPRODUCT($F70:$F74,I70:I74)+SUMPRODUCT($F64:$F68,I64:I68)+SUMPRODUCT($F58:$F62,I58:I62)+SUMPRODUCT($F76:$F79,I76:I79)+SUMPRODUCT($F52:$F56,I52:I56) | J10: =SUMPRODUCT($F70:$F74,J70:J74)+SUMPRODUCT($F64:$F68,J64:J68)+SUMPRODUCT($F58:$F62,J58:J62)+SUMPRODUCT($F76:$F79,J76:J79)+SUMPRODUCT($F52:$F56,J52:J56) | K10: =K51+K57+K63+K69+K75 -> 0 | L10: =L51+L57+L63+L69+L75 -> 0 | M10: =M51+M57+M63+M69+M75 -> 0 | N10: =N51+N57+N63+N69+N75 -> 0 | O10: =O51+O57+O63+O69+O75 -> 0 | P10: =P51+P57+P63+P69+P75 -> 0 | Q10: 0 | R10: 0 | S10: 0
A11: Total des Couts Directs : | F11: =F31+F42 | I11: =F42 | J11: =F31 | K11: =K31+K42 -> 0 | L11: =L31+L42 -> 0 | M11: =M31+M42 -> 0 | N11: =N31+N42 -> 0 | O11: =O31+O42 -> 0 | P11: =P31+P42 -> 0 | Q11: 0 | R11: 0 | S11: 0
A12: Prix de Revient Total : | F12: =F10+F11-G11 | G12: Saisie manuelle du PV : | I12: =I10+I11 -> 0 | J12: =J10+J11 -> 0 | K12: =K10+K11 -> 0 | L12: =L10+L11 -> 0 | M12: =M10+M11 -> 0 | N12: =N10+N11 -> 0 | O12: =O10+O11 -> 0 | P12: =P10+P11 -> 0 | Q12: 0 | R12: 0 | S12: 0
A13: Prix de Vente : | F13: =IF(G13="",SUM(K13:P13),G13) | G13: =DPGF!AB116 | I13: =SUM($K$18:$P$18) | J13: =SUM($K$17:$P$17) | K13: =K17+K18 -> 0 | L13: =L17+L18 -> 0 | M13: =M17+M18 -> 0 | N13: =N17+N18 -> 0 | O13: =O17+O18 -> 0 | P13: =P17+P18 -> 0 | Q13: 0 | R13: 0 | S13: 0
A14: dont Prorata : | F14: =SUMPRODUCT($K$14:$P$14,$K$13:$P$13) | G14: =IF(PV_FCI>0,F14/PV_FCI,0) | J14: % de PRORATA : | K14: 0 | L14: 0 | M14: 0 | N14: 0 | O14: 0 | P14: 0 | Q14: =E14 | R14: =F14 | S14: =G14
A15: Marge : | F15: =F13-F12-F14 | G15: =IF($F$13<>0,$F$15/$F$13,) | J15: Marge MAT : | K15: 0.2 | L15: 0.2 | M15: 0.2 | N15: 0.15 | O15: 0.2 | P15: 0.2 | Q15: 0.3 | R15: 0.3 | S15: 0.3
J16: Marge MO : | K16: 0.2 | L16: 0.2 | M16: 0.2 | N16: 0.15 | O16: 0.2 | P16: 0.2 | Q16: 0.3 | R16: 0.3 | S16: 0.3
A17: Feuilles DPGF | E17: Coûts directs | F17: Prix de Vente | J17: Prix de Vente MAT : | K17: =(K$31+(IF($F$51<>0,K$51*$J$51/$F$51,0)+IF($F$57<>0,K$57*$J$57/$F$57,0)+IF($F$63<>0,K$63*$J$63/$F$63,0)+IF($F$69<>0,K$69*$J$69/$F$69,0)+IF($F$76<>0,K$76*$J$76/$F$76,0)+$F$77*K$77))/(1-K$15-K$14-$D$78-$D$79) -> 0 | L17: =(L$31+(IF($F$51<>0,L$51*$J$51/$F$51,0)+IF($F$57<>0,L$57*$J$57/$F$57,0)+IF($F$63<>0,L$63*$J$63/$F$63,0)+IF($F$69<>0,L$69*$J$69/$F$69,0)+IF($F$76<>0,L$76*$J$76/$F$76,0)+$F$77*L$77))/(1-L$15-L$14-$D$78-$D$79) -> 0 | M17: =(M$31+(IF($F$51<>0,M$51*$J$51/$F$51,0)+IF($F$57<>0,M$57*$J$57/$F$57,0)+IF($F$63<>0,M$63*$J$63/$F$63,0)+IF($F$69<>0,M$69*$J$69/$F$69,0)+IF($F$76<>0,M$76*$J$76/$F$76,0)+$F$77*M$77))/(1-M$15-M$14-$D$78-$D$79) -> 0 | N17: =(N$31+(IF($F$51<>0,N$51*$J$51/$F$51,0)+IF($F$57<>0,N$57*$J$57/$F$57,0)+IF($F$63<>0,N$63*$J$63/$F$63,0)+IF($F$69<>0,N$69*$J$69/$F$69,0)+IF($F$76<>0,N$76*$J$76/$F$76,0)+$F$77*N$77))/(1-N$15-N$14-$D$78-$D$79) -> 0 | O17: =(O$31+(IF($F$51<>0,O$51*$J$51/$F$51,0)+IF($F$57<>0,O$57*$J$57/$F$57,0)+IF($F$63<>0,O$63*$J$63/$F$63,0)+IF($F$69<>0,O$69*$J$69/$F$69,0)+IF($F$76<>0,O$76*$J$76/$F$76,0)+$F$77*O$77))/(1-O$15-O$14-$D$78-$D$79) -> 0 | P17: =(P$31+(IF($F$51<>0,P$51*$J$51/$F$51,0)+IF($F$57<>0,P$57*$J$57/$F$57,0)+IF($F$63<>0,P$63*$J$63/$F$63,0)+IF($F$69<>0,P$69*$J$69/$F$69,0)+IF($F$76<>0,P$76*$J$76/$F$76,0)+$F$77*P$77))/(1-P$15-P$14-$D$78-$D$79) -> 0 | Q17: =(Q$31+(IF($F$51<>0,Q$51*$J$51/$F$51,0)+IF($F$57<>0,Q$57*$J$57/$F$57,0)+IF($F$63<>0,Q$63*$J$63/$F$63,0)+IF($F$69<>0,Q$69*$J$69/$F$69,0)+IF($F$76<>0,Q$76*$J$76/$F$76,0)+$F$77*Q$77))/(1-Q$15-Q$14-$D$78-$D$79) | R17: =(R$31+(IF($F$51<>0,R$51*$J$51/$F$51,0)+IF($F$57<>0,R$57*$J$57/$F$57,0)+IF($F$63<>0,R$63*$J$63/$F$63,0)+IF($F$69<>0,R$69*$J$69/$F$69,0)+IF($F$76<>0,R$76*$J$76/$F$76,0)+$F$77*R$77))/(1-R$15-R$14-$D$78-$D$79) | S17: =(S$31+(IF($F$51<>0,S$51*$J$51/$F$51,0)+IF($F$57<>0,S$57*$J$57/$F$57,0)+IF($F$63<>0,S$63*$J$63/$F$63,0)+IF($F$69<>0,S$69*$J$69/$F$69,0)+IF($F$76<>0,S$76*$J$76/$F$76,0)+$F$77*S$77))/(1-S$15-S$14-$D$78-$D$79)
A18: DPGF | J18: Prix de Vente MO : | K18: =(K$42+IF($F$51<>0,K$51*$I$51/$F$51,0)+IF($F$57<>0,K$57*$I$57/$F$57,0)+IF($F$63<>0,K$63*$I$63/$F$63,0)+IF($F$69<>0,K$69*$I$69/$F$69,0)+IF($F$76<>0,K$76*$I$76/$F$76,0))/(1-K$16-K$14-$D$78-$D$79) -> 0 | L18: =(L$42+IF($F$51<>0,L$51*$I$51/$F$51,0)+IF($F$57<>0,L$57*$I$57/$F$57,0)+IF($F$63<>0,L$63*$I$63/$F$63,0)+IF($F$69<>0,L$69*$I$69/$F$69,0)+IF($F$76<>0,L$76*$I$76/$F$76,0))/(1-L$16-L$14-$D$78-$D$79) -> 0 | M18: =(M$42+IF($F$51<>0,M$51*$I$51/$F$51,0)+IF($F$57<>0,M$57*$I$57/$F$57,0)+IF($F$63<>0,M$63*$I$63/$F$63,0)+IF($F$69<>0,M$69*$I$69/$F$69,0)+IF($F$76<>0,M$76*$I$76/$F$76,0))/(1-M$16-M$14-$D$78-$D$79) -> 0 | N18: =(N$42+IF($F$51<>0,N$51*$I$51/$F$51,0)+IF($F$57<>0,N$57*$I$57/$F$57,0)+IF($F$63<>0,N$63*$I$63/$F$63,0)+IF($F$69<>0,N$69*$I$69/$F$69,0)+IF($F$76<>0,N$76*$I$76/$F$76,0))/(1-N$16-N$14-$D$78-$D$79) -> 0 | O18: =(O$42+IF($F$51<>0,O$51*$I$51/$F$51,0)+IF($F$57<>0,O$57*$I$57/$F$57,0)+IF($F$63<>0,O$63*$I$63/$F$63,0)+IF($F$69<>0,O$69*$I$69/$F$69,0)+IF($F$76<>0,O$76*$I$76/$F$76,0))/(1-O$16-O$14-$D$78-$D$79) -> 0 | P18: =(P$42+IF($F$51<>0,P$51*$I$51/$F$51,0)+IF($F$57<>0,P$57*$I$57/$F$57,0)+IF($F$63<>0,P$63*$I$63/$F$63,0)+IF($F$69<>0,P$69*$I$69/$F$69,0)+IF($F$76<>0,P$76*$I$76/$F$76,0))/(1-P$16-P$14-$D$78-$D$79) -> 0 | Q18: =(Q$42+IF($F$51<>0,Q$51*$I$51/$F$51,0)+IF($F$57<>0,Q$57*$I$57/$F$57,0)+IF($F$63<>0,Q$63*$I$63/$F$63,0)+IF($F$69<>0,Q$69*$I$69/$F$69,0)+IF($F$76<>0,Q$76*$I$76/$F$76,0))/(1-Q$16-Q$14-$D$78-$D$79) | R18: =(R$42+IF($F$51<>0,R$51*$I$51/$F$51,0)+IF($F$57<>0,R$57*$I$57/$F$57,0)+IF($F$63<>0,R$63*$I$63/$F$63,0)+IF($F$69<>0,R$69*$I$69/$F$69,0)+IF($F$76<>0,R$76*$I$76/$F$76,0))/(1-R$16-R$14-$D$78-$D$79) | S18: =(S$42+IF($F$51<>0,S$51*$I$51/$F$51,0)+IF($F$57<>0,S$57*$I$57/$F$57,0)+IF($F$63<>0,S$63*$I$63/$F$63,0)+IF($F$69<>0,S$69*$I$69/$F$69,0)+IF($F$76<>0,S$76*$I$76/$F$76,0))/(1-S$16-S$14-$D$78-$D$79)
J19: Coef. K MAT : | K19: =IF(K$31>0,K$17/K$31,0) -> 0 | L19: =IF(L$31>0,L$17/L$31,0) -> 0 | M19: =IF(M$31>0,M$17/M$31,0) -> 0 | N19: =IF(N$31>0,N$17/N$31,0) -> 0 | O19: =IF(O$31>0,O$17/O$31,0) -> 0 | P19: =IF(P$31>0,P$17/P$31,0) -> 0 | Q19: =K19 | R19: =IF(R$31<>0,R$17/R$31,0) | S19: =IF(S$31<>0,S$17/S$31,0)
J20: Coef. K MO : | K20: =IF(K$42>0,K$18/$42:$42,0) -> 0 | L20: =IF(L$42>0,L$18/$42:$42,0) -> 0 | M20: =IF(M$42>0,M$18/$42:$42,0) -> 0 | N20: =IF(N$42>0,N$18/$42:$42,0) -> 0 | O20: =IF(O$42>0,O$18/$42:$42,0) -> 0 | P20: =IF(P$42>0,P$18/$42:$42,0) -> 0 | Q20: =K20 | R20: =IF(R$42<>0,R$18/$42:$42,0) | S20: =IF(S$42<>0,S$18/$42:$42,0)
I21: Commentaires
O27: Arrondi (P/U) : | P27: 2
A29: Postes | D29: Qté | E29: P/U | F29: P/T | G29: Remarques | I29: Répartition des Couts par Lot
I30: %/MO | J30: %/MAT | K30: =LOT_1 | L30: =L9 | M30: =M9 | N30: =N9 | O30: =O9 | P30: =P9 | Q30: VR1 | R30: VR2 | S30: VR3
B31: Matériel | F31: =SUM($K$31:$P$31) | K31: 36169.53 | M31: 153192.77 | N31: 29103.4
B32: CFA-70 : Equipements Visiophonie, Interphonie | F32: =SUM($K32:$P32) | M32: 122353.36
B33: CFA-30 : Equipements Vidéo Surveillance | F33: =SUM($K33:$P33) | M33: 24045.64
B34: SSI-00 : Câblage SSI | F34: =SUM($K34:$P34) | N34: 18798
B35: VDI-00 : Cables 4p | F35: =SUM($K35:$P35) | K35: 16876.54
B36: VDI-20 : Fibres Optiques Cables, connecteurs et accessoires | F36: =SUM($K36:$P36) | K36: 12132.71
B37: SSI-10 : DETECTION INCENDIE | F37: =SUM($K37:$P37) | N37: 10305.4
B38: CVC-60 : GTB / GTC | F38: =SUM($K38:$P38) | M38: 4510
B39: VDI-50 : Baies, Coffrets, Fermes et accessoires | F39: =SUM($K39:$P39) | K39: 3960.28
B40: CFA-95 : Réseau informatique (Switch, média converter, routeur …) | F40: =SUM($K40:$P40) | K40: 3200
B41: Autres familles | F41: =SUM($K41:$P41) | M41: 2283.77
B42: Main d'Œuvre montage et intégration | F42: =SUM($F$43:$F$50) | G42: Code MO | I42: =IF(($F$31+$F$42)>0,$F$42/($F$31+$F$42),) | J42: =IF(($F$31+$F$42)>0,$F$31/($F$31+$F$42),) | K42: =SUMPRODUCT($E$43:$E$50,K$43:K$50) | L42: =SUMPRODUCT($E$43:$E$50,L$43:L$50) -> 0 | M42: =SUMPRODUCT($E$43:$E$50,M$43:M$50) -> 0 | N42: =SUMPRODUCT($E$43:$E$50,N$43:N$50) -> 0 | O42: =SUMPRODUCT($E$43:$E$50,O$43:O$50) -> 0 | P42: =SUMPRODUCT($E$43:$E$50,P$43:P$50) -> 0 | Q42: =SUMPRODUCT($E$43:$E$50,Q$43:Q$50) -> 0 | R42: =SUMPRODUCT($E$43:$E$50,R$43:R$50) -> 0 | S42: =SUMPRODUCT($E$43:$E$50,S$43:S$50) -> 0
B43: X | C43: Monteur Cableur | D43: =SUM(K43:P43) | E43: 40 | F43: =E43*D43 | G43: STE-018 | I43: 1 | J43: =1-I43 | K43: 819 | M43: 272 | N43: 262.6
C44: Technicien FO | D44: =SUM(K44:P44) -> 0 | E44: 48 | F44: =E44*D44 -> 0 | G44: STE-596 | I44: 1 | J44: =1-I44 -> 0
C45: Technicien CFO | D45: =SUM(K45:P45) -> 0 | E45: 48 | F45: =E45*D45 -> 0 | G45: STE-338 | I45: 1 | J45: =1-I45 -> 0
B46: X | C46: Technicien Cfa | D46: =SUM(K46:P46) | E46: 60 | F46: =E46*D46 | G46: STE-163 | I46: 1 | J46: =1-I46 -> 0 | K46: 152.5 | M46: 188.5 | N46: 90
C47: Technicien SSI | D47: =SUM(K47:P47) -> 0 | E47: 62 | F47: =E47*D47 -> 0 | G47: STE-136 | I47: 1 | J47: =1-I47 -> 0
C48: Technicien CVC | D48: =SUM(K48:P48) -> 0 | E48: 62 | F48: =E48*D48 -> 0 | G48: STE-335 | I48: 1 | J48: =1-I48 -> 0
...

Sheet PARA DPGF
A1: Bordereaux Client (DPGF, DQE, BOM ….) | E1: Numéro de Ligne | F1: Numéros des Colonnes | R1: Colonnes de Calcul | AA1: Colonnes de Profils de MO
A2: Création | B2: Participe au Récap | C2: Nom de la Feuille | D2: Lot par défaut | E2: Dernière ligne de Titre | F2: Constructeur | G2: Référence | H2: Description matériel | I2: Qté Achat | J2: Unité | K2: Quantité | L2: PU MAT | M2: PU MO | N2: PU MAT+MO | O2: PT MAT | P2: PT MO | Q2: PT MAT+MO | R2: LOT | S2: FAMILLE | T2: PRU MAT | U2: PRT MAT | V2: PRU MO | W2: PRT MO | X2: PRT | Y2: KMAT | Z2: KMO | AA2: Ratio MO1 | AB2: HRS MO1 Total | AC2: Ratio MO2 | AD2: HRS MO2 Total | AE2: Ratio MO3 | AF2: HRS MO3 Total | AG2: Ratio MO4 | AH2: HRS MO4 Total
A3: 43634.677 | B3: X | C3: DPGF | D3: VDI | E3: 15 | F3: =COLUMN(DPGF!$E$15) -> 5 | G3: =COLUMN(DPGF!$F$15) -> 6 | H3: =COLUMN(DPGF!$G$15) -> 7 | J3: =COLUMN(DPGF!$H$15) -> 8 | K3: =COLUMN(DPGF!$I$15) -> 9 | L3: =COLUMN(DPGF!$W$15) -> 23 | M3: =COLUMN(DPGF!$X$15) -> 24 | N3: 25 | O3: =COLUMN(DPGF!$Z$15) -> 26 | P3: =COLUMN(DPGF!$AA$15) -> 27 | Q3: 28 | R3: =COLUMN(DPGF!$C$15) -> 3 | S3: =COLUMN(DPGF!$D$15) -> 4 | T3: =COLUMN(DPGF!$J$15) -> 10 | U3: =COLUMN(DPGF!$K$15) -> 11 | V3: =COLUMN(DPGF!$R$15) -> 18 | W3: =COLUMN(DPGF!$S$15) -> 19 | X3: =COLUMN(DPGF!$T$15) -> 20 | Y3: =COLUMN(DPGF!$U$15) -> 21 | Z3: =COLUMN(DPGF!$V$15) -> 22 | AA3: =COLUMN(DPGF!$L$15) -> 12 | AB3: =COLUMN(DPGF!$M$15) -> 13 | AC3: =COLUMN(DPGF!$N$15) -> 14 | AD3: =COLUMN(DPGF!$O$15) -> 15 | AE3: =COLUMN(DPGF!$P$15) -> 16 | AF3: =COLUMN(DPGF!$Q$15) -> 17

Sheet DPGF
A5: PROSYB
A6: 3 av Jacques Chaban Delmas Roissy
A7: 77 680 Roissy en Brie
A8: France
A10: Contact : | B10: Woody SEALE
A11: Tel: | B11: 07.71.69.47.99
A12: Email: | B12: woody.seale@prosyb.com
A14: REF. | B14: DESIGNATION | C14: Equipements | H14: Unité | I14: Quantité | L14: Monteur Cableur | M14: =TXMO1 -> 40 | N14: Technicien Cfa | O14: =TXMO4 -> 60 | P14: RT Etudes | Q14: =TXMO7 -> 75 | Y14: Prix de vente
C15: LOT | D15: FAMILLE | E15: CONSTRUCTEUR | F15: REFERENCE | G15: DESCRIPTION | J15: PRU MAT | K15: PRT MAT | L15: RATIO MO | M15: HRS T | N15: RATIO MO | O15: HRS T | P15: RATIO MO | Q15: HRS T | R15: PRU MO | S15: PRT MO | T15: PR TOTAL | U15: Coef MAT | V15: Coef MO | W15: PU MAT | X15: PU MO | Y15: P.U | Z15: PT MAT | AA15: PT MO | AB15: PRIX TOTAL
B17: OBJET : KHAZNA ORY01 — Fouju (77) — Installations provisoires base vie & chantier — Lot courants faibles : informatique, audiovisuel, affichage, SSI, vidéosurveillance, GTB (DPGF lots 4 à 7)
A19: 1 | B19: INFORMATIQUE, AUDIOVISUEL & AFFICHAGES — PHASE 2 (2 MOIS) — TVA 20 %
B20: Informatique cœur de réseau
A21: 1.1 | B21: Fourniture, pose et raccordement répartiteur informatique principal dans poste énergie Hub 1, incluant switch PoE (switch d'agrégation vidéoprotection fourni par PROSYB) | C21: VDI | D21: VDI-50 | E21: OCTET PLUS / LIEN'K | F21: BAI4288CN | G21: MO : Pose baie 42U + équipement (4 h, réf. baie GTB SAFRAN) + pose switch L3 (1 h) ; paramétrage en ligne 14 | Fourniture Octet Plus devis DE044128 du 15/10/2026 (ZVK EasyLan, garantie système 25 ans ; baies LIEN'K), baie 42U 800×800 BAI4288CN (615,40 €) + bandeau 8 PC COF BAND8PC+VOY (19,45 €) = 634.85 €, ajoutés au switch L3 S57244-B0 CCF (786,03 €) → 1420.88 €. Tiroirs optiques comptés dans les lignes fibre. Pose/MO à ajouter. | H21: ens | I21: 1 | J21: 1420.88 | K21: =J21*$I21 | M21: =L21*$I21 | N21: 5 | O21: =N21*$I21 | Q21: =P21*$I21 | R21: =$L21*$M$14+$N21*$O$14+$P21*$Q$14 | S21: =R21*$I21 | T21: =$S21+$K21 | U21: =HLOOKUP($C21,Recap_FCI!$K$9:$S$20,11,FALSE) | V21: =HLOOKUP($C21,Recap_FCI!$K$9:$S$20,12,FALSE) | W21: =$J21*$U21 | X21: =$R21*$V21 | Y21: =X21+W21 | Z21: =$W21*$I21 | AA21: =$X21*$I21 | AB21: =$Y21*$I21
A22: 1.2 | B22: Fourniture, pose et raccordement répartiteur informatique principal dans poste énergie Hub 2 — switch fourni par EXYTE, pose et paramétrage PROSYB | C22: VDI | D22: VDI-50 | E22: OCTET PLUS / LIEN'K | F22: BAI4288CN | G22: MO : Pose baie 42U + équipement (4 h) + pose switch EXYTE (1 h) | Fourniture Octet Plus devis DE044128 du 15/10/2026 (ZVK EasyLan, garantie système 25 ans ; baies LIEN'K), baie 42U 800×800 BAI4288CN + bandeau 8 PC = 634.85 €. Switch informatique fourni par EXYTE (pose et paramétrage PROSYB, MO à chiffrer). | H22: ens | I22: 1 | J22: 634.85 | K22: =J22*$I22 | M22: =L22*$I22 | N22: 5 | O22: =N22*$I22 | Q22: =P22*$I22 | R22: =$L22*$M$14+$N22*$O$14+$P22*$Q$14 | S22: =R22*$I22 | T22: =$S22+$K22 | U22: =HLOOKUP($C22,Recap_FCI!$K$9:$S$20,11,FALSE) | V22: =HLOOKUP($C22,Recap_FCI!$K$9:$S$20,12,FALSE) | W22: =$J22*$U22 | X22: =$R22*$V22 | Y22: =X22+W22 | Z22: =$W22*$I22 | AA22: =$X22*$I22 | AB22: =$Y22*$I22
A23: 1.3 | B23: Fourniture, pose et raccordement répartiteur informatique secondaire Est 1 — switch fourni par EXYTE, pose et paramétrage PROSYB | C23: VDI | D23: VDI-50 | G23: MO : Intégration tiroir optique, panneau et switch EXYTE dans coffret SPIE (réf. coffret Vaires 2 h) | Coffret IP55 FOURNI ET POSÉ PAR SPIE (Ahmed, lot électricité) : retiré de l'offre et du devis Octet Plus DE044128 (COF12645MIP55 + bandeau). PROSYB installe dans ce coffret le tiroir optique et le panneau Cat. 6A (compatibilité 19"/rail DIN à valider avec SPIE). Switch informatique fourni par EXYTE (pose et paramétrage PROSYB, MO à chiffrer). | H23: ens | I23: 1 | K23: =J23*$I23 | M23: =L23*$I23 | N23: 2 | O23: =N23*$I23 | Q23: =P23*$I23 | R23: =$L23*$M$14+$N23*$O$14+$P23*$Q$14 | S23: =R23*$I23 | T23: =$S23+$K23 | U23: =HLOOKUP($C23,Recap_FCI!$K$9:$S$20,11,FALSE) | V23: =HLOOKUP($C23,Recap_FCI!$K$9:$S$20,12,FALSE) | W23: =$J23*$U23 | X23: =$R23*$V23 | Y23: =X23+W23 | Z23: =$W23*$I23 | AA23: =$X23*$I23 | AB23: =$Y23*$I23
A24: 1.4 | B24: Fourniture, pose et raccordement répartiteur informatique secondaire Est 2 — switch fourni par EXYTE, pose et paramétrage PROSYB | C24: VDI | D24: VDI-50 | G24: MO : Idem Est 1 | Coffret IP55 FOURNI ET POSÉ PAR SPIE (Ahmed, lot électricité) : retiré de l'offre et du devis Octet Plus DE044128 (COF12645MIP55 + bandeau). PROSYB installe dans ce coffret le tiroir optique et le panneau Cat. 6A (compatibilité 19"/rail DIN à valider avec SPIE). Switch informatique fourni par EXYTE (pose et paramétrage PROSYB, MO à chiffrer). | H24: ens | I24: 1 | K24: =J24*$I24 | M24: =L24*$I24 | N24: 2 | O24: =N24*$I24 | Q24: =P24*$I24 | R24: =$L24*$M$14+$N24*$O$14+$P24*$Q$14 | S24: =R24*$I24 | T24: =$S24+$K24 | U24: =HLOOKUP($C24,Recap_FCI!$K$9:$S$20,11,FALSE) | V24: =HLOOKUP($C24,Recap_FCI!$K$9:$S$20,12,FALSE) | W24: =$J24*$U24 | X24: =$R24*$V24 | Y24: =X24+W24 | Z24: =$W24*$I24 | AA24: =$X24*$I24 | AB24: =$Y24*$I24
A25: 1.5 | B25: Fourniture, pose et raccordement répartiteur informatique secondaire Est 3 — switch fourni par EXYTE, pose et paramétrage PROSYB | C25: VDI | D25: VDI-50 | G25: MO : Idem Est 1 | Coffret IP55 FOURNI ET POSÉ PAR SPIE (Ahmed, lot électricité) : retiré de l'offre et du devis Octet Plus DE044128 (COF12645MIP55 + bandeau). PROSYB installe dans ce coffret le tiroir optique et le panneau Cat. 6A (compatibilité 19"/rail DIN à valider avec SPIE). Switch informatique fourni par EXYTE (pose et paramétrage PROSYB, MO à chiffrer). | H25: ens | I25: 1 | K25: =J25*$I25 | M25: =L25*$I25 | N25: 2 | O25: =N25*$I25 | Q25: =P25*$I25 | R25: =$L25*$M$14+$N25*$O$14+$P25*$Q$14 | S25: =R25*$I25 | T25: =$S25+$K25 | U25: =HLOOKUP($C25,Recap_FCI!$K$9:$S$20,11,FALSE) | V25: =HLOOKUP($C25,Recap_FCI!$K$9:$S$20,12,FALSE) | W25: =$J25*$U25 | X25: =$R25*$V25 | Y25: =X25+W25 | Z25: =$W25*$I25 | AA25: =$X25*$I25 | AB25: =$Y25*$I25
A26: 1.6 | B26: Fourniture, pose et raccordement répartiteur informatique secondaire Ouest 1 — switch fourni par EXYTE, pose et paramétrage PROSYB | C26: VDI | D26: VDI-50 | G26: MO : Idem Est 1 | Coffret IP55 FOURNI ET POSÉ PAR SPIE (Ahmed, lot électricité) : retiré de l'offre et du devis Octet Plus DE044128 (COF12645MIP55 + bandeau). PROSYB installe dans ce coffret le tiroir optique et le panneau Cat. 6A (compatibilité 19"/rail DIN à valider avec SPIE). Switch informatique fourni par EXYTE (pose et paramétrage PROSYB, MO à chiffrer). | H26: ens | I26: 1 | K26: =J26*$I26 | M26: =L26*$I26 | N26: 2 | O26: =N26*$I26 | Q26: =P26*$I26 | R26: =$L26*$M$14+$N26*$O$14+$P26*$Q$14 | S26: =R26*$I26 | T26: =$S26+$K26 | U26: =HLOOKUP($C26,Recap_FCI!$K$9:$S$20,11,FALSE) | V26: =HLOOKUP($C26,Recap_FCI!$K$9:$S$20,12,FALSE) | W26: =$J26*$U26 | X26: =$R26*$V26 | Y26: =X26+W26 | Z26: =$W26*$I26 | AA26: =$X26*$I26 | AB26: =$Y26*$I26
A27: 1.7 | B27: Fourniture, pose et raccordement répartiteur informatique secondaire Ouest 2 — switch fourni par EXYTE, pose et paramétrage PROSYB | C27: VDI | D27: VDI-50 | G27: MO : Idem Est 1 | Coffret IP55 FOURNI ET POSÉ PAR SPIE (Ahmed, lot électricité) : retiré de l'offre et du devis Octet Plus DE044128 (COF12645MIP55 + bandeau). PROSYB installe dans ce coffret le tiroir optique et le panneau Cat. 6A (compatibilité 19"/rail DIN à valider avec SPIE). Switch informatique fourni par EXYTE (pose et paramétrage PROSYB, MO à chiffrer). | H27: ens | I27: 1 | K27: =J27*$I27 | M27: =L27*$I27 | N27: 2 | O27: =N27*$I27 | Q27: =P27*$I27 | R27: =$L27*$M$14+$N27*$O$14+$P27*$Q$14 | S27: =R27*$I27 | T27: =$S27+$K27 | U27: =HLOOKUP($C27,Recap_FCI!$K$9:$S$20,11,FALSE) | V27: =HLOOKUP($C27,Recap_FCI!$K$9:$S$20,12,FALSE) | W27: =$J27*$U27 | X27: =$R27*$V27 | Y27: =X27+W27 | Z27: =$W27*$I27 | AA27: =$X27*$I27 | AB27: =$Y27*$I27
A28: 1.8 | B28: Fourniture, pose et raccordement boucle fibre OS2 12 brins autocicatrisante depuis le répartiteur principal poste énergie Hub 1 vers répartiteurs secondaires Est 1, Est 2, Ouest 1, Ouest 2 et Ouest 3 | C28: VDI | D28: VDI-20 | E28: OCTET PLUS / ZVK | F28: ZVKLUZB12OS2 | G28: MO : Tirage fibre en fourreaux 2 900 ml à 2,5 h/100 ml (hypothèse optimiste, gros tronçons) ; fusion et tests par Octet Plus | Fourniture Octet Plus devis DE044128 du 15/10/2026 (ZVK EasyLan, garantie système 25 ans ; baies LIEN'K), boucle OS2 12 brins anti-rongeurs ZVKLUZB12OS2, 6 tronçons ≈ 2 900 ml : câble (3728.57 €) + par tronçon tiroirs LC, fusion de 24 pigtails, test photométrie Fluke Versiv2 et jarretières (561.06 € × 6) = 7094.92 €. Fusion et tests fibre réalisés par Octet Plus. | H28: ens | I28: 1 | J28: 7094.92 | K28: =J28*$I28 | L28: 72.5 | M28: =L28*$I28 | O28: =N28*$I28 | Q28: =P28*$I28 | R28: =$L28*$M$14+$N28*$O$14+$P28*$Q$14 | S28: =R28*$I28 | T28: =$S28+$K28 | U28: =HLOOKUP($C28,Recap_FCI!$K$9:$S$20,11,FALSE) | V28: =HLOOKUP($C28,Recap_FCI!$K$9:$S$20,12,FALSE) | W28: =$J28*$U28 | X28: =$R28*$V28 | Y28: =X28+W28 | Z28: =$W28*$I28 | AA28: =$X28*$I28 | AB28: =$Y28*$I28
A29: 1.9 | B29: Fourniture, pose et raccordement liaison fibre OS2 12 brins autocicatrisante depuis le répartiteur principal poste énergie Hub 1 vers le répartiteur princiapl Hub 2 | C29: VDI | D29: VDI-20 | E29: OCTET PLUS / ZVK | F29: ZVKLUZB12OS2 | G29: MO : Tirage 450 ml à 2,5 h/100 ml | Fourniture Octet Plus devis DE044128 du 15/10/2026 (ZVK EasyLan, garantie système 25 ans ; baies LIEN'K), liaison OS2 12 brins ≈ 450 ml : câble (578.57 €) + tiroirs, fusion, tests, jarretières (561.06 €) = 1139.63 €. | H29: ens | I29: 1 | J29: 1139.63 | K29: =J29*$I29 | L29: 11.25 | M29: =L29*$I29 | O29: =N29*$I29 | Q29: =P29*$I29 | R29: =$L29*$M$14+$N29*$O$14+$P29*$Q$14 | S29: =R29*$I29 | T29: =$S29+$K29 | U29: =HLOOKUP($C29,Recap_FCI!$K$9:$S$20,11,FALSE) | V29: =HLOOKUP($C29,Recap_FCI!$K$9:$S$20,12,FALSE) | W29: =$J29*$U29 | X29: =$R29*$V29 | Y29: =X29+W29 | Z29: =$W29*$I29 | AA29: =$X29*$I29 | AB29: =$Y29*$I29
A30: 1.10 | B30: Paramétrage équipements informatiques | C30: VDI | D30: DIV-70 | G30: MO : Paramétrage P2 : switch L3 3 h + Hub 2 3 h + 5 secondaires × 1,5 h (réf. Vaires) + anneau/VLAN/supervision 6 h ; BE : plan d'adressage, VLAN, synoptiques, DOE IT (16 h) | | H30: ens | I30: 1 | K30: =J30*$I30 | M30: =L30*$I30 | N30: 20 | O30: =N30*$I30 | P30: 16 | Q30: =P30*$I30 | R30: =$L30*$M$14+$N30*$O$14+$P30*$Q$14 | S30: =R30*$I30 | T30: =$S30+$K30 | U30: =HLOOKUP($C30,Recap_FCI!$K$9:$S$20,11,FALSE) | V30: =HLOOKUP($C30,Recap_FCI!$K$9:$S$20,12,FALSE) | W30: =$J30*$U30 | X30: =$R30*$V30 | Y30: =X30+W30 | Z30: =$W30*$I30 | AA30: =$X30*$I30 | AB30: =$Y30*$I30
A31: 1.11 | B31: Test de réfléctométrie | C31: VDI | D31: DIV-80 | G31: MO : Réflectométrie/photométrie réalisée par Octet Plus (incluse dans les lignes fibre) | Réflectométrie/photométrie fibre incluse dans les lignes fibre (prestation Octet Plus : raccordement et test 1310/1550 nm dans les deux sens + photométrie ISO/IEC 14763-3, dossier de mesures). | H31: ens | I31: 1 | K31: =J31*$I31 | M31: =L31*$I31 | O31: =N31*$I31 | Q31: =P31*$I31 | R31: =$L31*$M$14+$N31*$O$14+$P31*$Q$14 | S31: =R31*$I31 | T31: =$S31+$K31 | U31: =HLOOKUP($C31,Recap_FCI!$K$9:$S$20,11,FALSE) | V31: =HLOOKUP($C31,Recap_FCI!$K$9:$S$20,12,FALSE) | W31: =$J31*$U31 | X31: =$R31*$V31 | Y31: =X31+W31 | Z31: =$W31*$I31 | AA31: =$X31*$I31 | AB31: =$Y31*$I31
B32: Informatique îlots 1 et 2
A33: 1.12 | B33: Fourniture, pose et raccordement liaison cuivre répartiteur informatique principal vers équipements (postes de travail CAD + bornes WiFi), 12 prises RJ45 par îlot, soit 24 prises RJ45 au total | C33: VDI | D33: VDI-00 | E33: OCTET PLUS / ZVK | F33: ZVKCEFF1212K | G33: MO : 24 liens × 1,2 h (réf. Vaires 1,5 h/lien RJ45 30 m, optimisé en volume) | Fourniture Octet Plus devis DE044128 du 15/10/2026 (ZVK EasyLan, garantie système 25 ans ; baies LIEN'K), 24 liens Cat. 6A F/FTP 500 MHz LSFROH ZVKCEFF1212K ≈ 35 m : câble + 2 noyaux FixLink CKFAK001 + plastron 45×45 + 2 cordons Cat. 6A 1 m + quote-part platines 24 ports/passe-cordons = 770.76 €. POSE CUIVRE NON INCLUSE au devis Octet Plus (seule la fibre est raccordée) : MO PROSYB à ajouter. | H33: ens | I33: 1 | J33: 770.76 | K33: =J33*$I33 | L33: 28.8 | M33: =L33*$I33 | O33: =N33*$I33 | Q33: =P33*$I33 | R33: =$L33*$M$14+$N33*$O$14+$P33*$Q$14 | S33: =R33*$I33 | T33: =$S33+$K33 | U33: =HLOOKUP($C33,Recap_FCI!$K$9:$S$20,11,FALSE) | V33: =HLOOKUP($C33,Recap_FCI!$K$9:$S$20,12,FALSE) | W33: =$J33*$U33 | X33: =$R33*$V33 | Y33: =X33+W33 | Z33: =$W33*$I33 | AA33: =$X33*$I33 | AB33: =$Y33*$I33
A34: 1.13 | B34: Pose et raccordement borne WiFi | C34: VDI | D34: CFA-95 | G34: MO : 4 bornes × (0,75 h monteur + 0,25 h tech) (réf. Vaires 1 h + 0,5 h, optimisé) | | H34: u | I34: 4 | K34: =J34*$I34 | L34: 0.75 | M34: =L34*$I34 | N34: 0.25 | O34: =N34*$I34 | Q34: =P34*$I34 | R34: =$L34*$M$14+$N34*$O$14+$P34*$Q$14 | S34: =R34*$I34 | T34: =$S34+$K34 | U34: =HLOOKUP($C34,Recap_FCI!$K$9:$S$20,11,FALSE) | V34: =HLOOKUP($C34,Recap_FCI!$K$9:$S$20,12,FALSE) | W34: =$J34*$U34 | X34: =$R34*$V34 | Y34: =X34+W34 | Z34: =$W34*$I34 | AA34: =$X34*$I34 | AB34: =$Y34*$I34
A35: 1.14 | B35: Fourniture, pose et raccordement équipements audiovisuel salle de réunion (Un écran 85" par salle de réunion, avec enceinte caméra combinée + kit 5x micros déportés connectés) | C35: CFA | D35: CFA-70 | E35: SONEPAR | F35: 0014640130 | G35: MO : Fourniture ajoutée : 3 Rally Mic Pod supplémentaires × 252 € (estimatif, à recoter Sonepar : 4 Mic Pod/salle). MO : montage chariot + écran 86" à 2 (3 h), câblage barre/micros/lecteur/switch (2 h), essais Teams/USB (1 h) | Fourniture seule SONEPAR offre 0014640130 du 16/10/2026 (valable 31/10/2026), prix par salle : écran 86" 4K iiyama LH8665UHSB-B1 (2 188,50 €) + chariot mobile Chief Voyager LSCUW (920,00 €) + étagère Chief SCSSW (216,00 €) + barre visio Logitech Rally Bar (3 400,00 €) + micro LOG025 (252,00 €) + lecteur Navori StiX 3800 (450,00 €) + licence Navori PRD-1011571 (450,00 €) + switch PoE 8 ports TP-Link SG2210MP (164,19 €) + cordons HDMI 10 m (42,89 €) et 2 m (11,58 €) + D3E (1,49 €) + quote-part port (6,00 €) = 8 102,65 €. À RECOTER : micro coté = micro d'extension MeetUp, NON compatible Rally Bar (doc. Logitech) ; le DCE demande 5 micros, mémoire = 4 Logitech Rally Mic Pod 989-000430 (maximum Rally Bar) → demander prix Sonepar. Chariot Chief annoncé 50-85", écran 86"/49 kg (charge 79 kg OK) : compatibilité à faire valider. Variante Rally Bar Huddle (1 850 €) non retenue. Pose/câblage/paramétrage/MO à ajouter. | H35: u | I35: 3 | J35: 8858.65 | K35: =J35*$I35 | L35: 3 | M35: =L35*$I35 | N35: 3 | O35: =N35*$I35 | Q35: =P35*$I35 | R35: =$L35*$M$14+$N35*$O$14+$P35*$Q$14 | S35: =R35*$I35 | T35: =$S35+$K35 | U35: =HLOOKUP($C35,Recap_FCI!$K$9:$S$20,11,FALSE) | V35: =HLOOKUP($C35,Recap_FCI!$K$9:$S$20,12,FALSE) | W35: =$J35*$U35 | X35: =$R35*$V35 | Y35: =X35+W35 | Z35: =$W35*$I35 | AA35: =$X35*$I35 | AB35: =$Y35*$I35
A36: 1.15 | B36: Recettage cuivre | C36: VDI | D36: DIV-80 | G36: MO : Certification classe EA : 24 liens × 0,1 h + rapport 1 h (certificateur PROSYB supposé disponible) | Certification cuivre classe EA non chiffrée par Octet Plus : à réaliser par PROSYB (testeur de certification) ou à demander à Octet Plus. | H36: ens | I36: 1 | K36: =J36*$I36 | M36: =L36*$I36 | N36: 3.4 | O36: =N36*$I36 | Q36: =P36*$I36 | R36: =$L36*$M$14+$N36*$O$14+$P36*$Q$14 | S36: =R36*$I36 | T36: =$S36+$K36 | U36: =HLOOKUP($C36,Recap_FCI!$K$9:$S$20,11,FALSE) | V36: =HLOOKUP($C36,Recap_FCI!$K$9:$S$20,12,FALSE) | W36: =$J36*$U36 | X36: =$R36*$V36 | Y36: =X36+W36 | Z36: =$W36*$I36 | AA36: =$X36*$I36 | AB36: =$Y36*$I36
AB38: =SUBTOTAL(9,AB20:AB36)
A39: 2 | B39: INFORMATIQUE, AUDIOVISUEL & AFFICHAGES — PHASE 3 (5 MOIS) — TVA 20 %
B40: Informatique cœur de réseau
A41: 2.1 | B41: Sans objet | C41: VDI | D41: VDI-00 | H41: ens | I41: 1 | K41: =J41*$I41 | M41: =L41*$I41 | O41: =N41*$I41 | Q41: =P41*$I41 | R41: =$L41*$M$14+$N41*$O$14+$P41*$Q$14 | S41: =R41*$I41 | T41: =$S41+$K41 | U41: =HLOOKUP($C41,Recap_FCI!$K$9:$S$20,11,FALSE) | V41: =HLOOKUP($C41,Recap_FCI!$K$9:$S$20,12,FALSE) | W41: =$J41*$U41 | X41: =$R41*$V41 | Y41: =X41+W41 | Z41: =$W41*$I41 | AA41: =$X41*$I41 | AB41: =$Y41*$I41
B42: Informatique îlots 3 à 10
A43: 2.2 | B43: Fourniture, pose et raccordement liaisons cuivre répartiteur informatique principal vers équipements (postes de travail CAD + bornes WiFi), 12 prises RJ45 par îlot, soit 96 prises RJ45 au total | C43: VDI | D43: VDI-00 | E43: OCTET PLUS / ZVK | F43: ZVKCEFF1212K | G43: MO : 96 liens × 1,2 h | Fourniture Octet Plus devis DE044128 du 15/10/2026 (ZVK EasyLan, garantie système 25 ans ; baies LIEN'K), 96 liens Cat. 6A F/FTP ≈ 35 m, même composition que P2 = 3083.05 €. Pose cuivre non incluse : MO PROSYB à ajouter. | H43: ens | I43: 1 | J43: 3083.05 | K43: =J43*$I43 | L43: 115.2 | M43: =L43*$I43 | O43: =N43*$I43 | Q43: =P43*$I43 | R43: =$L43*$M$14+$N43*$O$14+$P43*$Q$14 | S43: =R43*$I43 | T43: =$S43+$K43 | U43: =HLOOKUP($C43,Recap_FCI!$K$9:$S$20,11,FALSE) | V43: =HLOOKUP($C43,Recap_FCI!$K$9:$S$20,12,FALSE) | W43: =$J43*$U43 | X43: =$R43*$V43 | Y43: =X43+W43 | Z43: =$W43*$I43 | AA43: =$X43*$I43 | AB43: =$Y43*$I43
A44: 2.3 | B44: Fourniture, pose et raccordement borne WiFi | C44: VDI | D44: CFA-95 | E44: UBIQUITI (estimatif) | F44: U6 Pro | G44: MO : Fourniture borne Wi-Fi 6 PoE type Ubiquiti U6 Pro 160 € (estimatif, prix budgétaire de repli) ; pose 0,75 h + 0,25 h | | H44: u | I44: 20 | J44: 160 | K44: =J44*$I44 | L44: 0.75 | M44: =L44*$I44 | N44: 0.25 | O44: =N44*$I44 | Q44: =P44*$I44 | R44: =$L44*$M$14+$N44*$O$14+$P44*$Q$14 | S44: =R44*$I44 | T44: =$S44+$K44 | U44: =HLOOKUP($C44,Recap_FCI!$K$9:$S$20,11,FALSE) | V44: =HLOOKUP($C44,Recap_FCI!$K$9:$S$20,12,FALSE) | W44: =$J44*$U44 | X44: =$R44*$V44 | Y44: =X44+W44 | Z44: =$W44*$I44 | AA44: =$X44*$I44 | AB44: =$Y44*$I44
A45: 2.4 | B45: Fourniture, pose et raccordement équipements audiovisuel salle de réunion (Un écran 85" par salle de réunion, avec enceinte caméra combinée + kit 5x micros déportés connectés) | C45: CFA | D45: CFA-70 | E45: SONEPAR | F45: 0014640130 | G45: MO : Idem P2 | Fourniture seule SONEPAR offre 0014640130 du 16/10/2026 (valable 31/10/2026), prix par salle : écran 86" 4K iiyama LH8665UHSB-B1 (2 188,50 €) + chariot mobile Chief Voyager LSCUW (920,00 €) + étagère Chief SCSSW (216,00 €) + barre visio Logitech Rally Bar (3 400,00 €) + micro LOG025 (252,00 €) + lecteur Navori StiX 3800 (450,00 €) + licence Navori PRD-1011571 (450,00 €) + switch PoE 8 ports TP-Link SG2210MP (164,19 €) + cordons HDMI 10 m (42,89 €) et 2 m (11,58 €) + D3E (1,49 €) + quote-part port (6,00 €) = 8 102,65 €. À RECOTER : micro coté = micro d'extension MeetUp, NON compatible Rally Bar (doc. Logitech) ; le DCE demande 5 micros, mémoire = 4 Logitech Rally Mic Pod 989-000430 (maximum Rally Bar) → demander prix Sonepar. Chariot Chief annoncé 50-85", écran 86"/49 kg (charge 79 kg OK) : compatibilité à faire valider. Variante Rally Bar Huddle (1 850 €) non retenue. Pose/câblage/paramétrage/MO à ajouter. | H45: u | I45: 7 | J45: 8858.65 | K45: =J45*$I45 | L45: 3 | M45: =L45*$I45 | N45: 3 | O45: =N45*$I45 | Q45: =P45*$I45 | R45: =$L45*$M$14+$N45*$O$14+$P45*$Q$14 | S45: =R45*$I45 | T45: =$S45+$K45 | U45: =HLOOKUP($C45,Recap_FCI!$K$9:$S$20,11,FALSE) | V45: =HLOOKUP($C45,Recap_FCI!$K$9:$S$20,12,FALSE) | W45: =$J45*$U45 | X45: =$R45*$V45 | Y45: =X45+W45 | Z45: =$W45*$I45 | AA45: =$X45*$I45 | AB45: =$Y45*$I45
A46: 2.5 | B46: Recettage cuivre | C46: VDI | D46: DIV-80 | G46: MO : Certification 96 liens × 0,1 h + rapport 1 h | Certification cuivre classe EA non chiffrée par Octet Plus : PROSYB ou demande complémentaire. | H46: ens | I46: 1 | K46: =J46*$I46 | M46: =L46*$I46 | N46: 10.6 | O46: =N46*$I46 | Q46: =P46*$I46 | R46: =$L46*$M$14+$N46*$O$14+$P46*$Q$14 | S46: =R46*$I46 | T46: =$S46+$K46 | U46: =HLOOKUP($C46,Recap_FCI!$K$9:$S$20,11,FALSE) | V46: =HLOOKUP($C46,Recap_FCI!$K$9:$S$20,12,FALSE) | W46: =$J46*$U46 | X46: =$R46*$V46 | Y46: =X46+W46 | Z46: =$W46*$I46 | AA46: =$X46*$I46 | AB46: =$Y46*$I46
B47: Informatique chantier
A48: 2.6 | B48: Fourniture, pose et raccordement répartiteur secondaire bâtiments annexes | C48: VDI | D48: VDI-20 | E48: OCTET PLUS / ZVK | F48: ZVKLUZB12OS2 | G48: MO : Par annexe : tirage fibre 150 ml (3,75 h) + intégration dans coffret SPIE (2 h) | Fourniture Octet Plus devis DE044128 du 15/10/2026 (ZVK EasyLan, garantie système 25 ans ; baies LIEN'K), par annexe : liaison OS2 12 brins ≈ 150 ml avec tiroir, fusion, tests = 753.92 €. Coffret IP55 fourni et posé par SPIE (retiré du devis Octet Plus). Switch fourni par EXYTE. | H48: u | I48: 2 | J48: 753.92 | K48: =J48*$I48 | L48: 3.75 | M48: =L48*$I48 | N48: 2 | O48: =N48*$I48 | Q48: =P48*$I48 | R48: =$L48*$M$14+$N48*$O$14+$P48*$Q$14 | S48: =R48*$I48 | T48: =$S48+$K48 | U48: =HLOOKUP($C48,Recap_FCI!$K$9:$S$20,11,FALSE) | V48: =HLOOKUP($C48,Recap_FCI!$K$9:$S$20,12,FALSE) | W48: =$J48*$U48 | X48: =$R48*$V48 | Y48: =X48+W48 | Z48: =$W48*$I48 | AA48: =$X48*$I48 | AB48: =$Y48*$I48
A49: 2.7 | B49: Fourniture, pose et raccordement liaisons RJ45 CAT6A F/STP bâtiments techniques & extérieurs | C49: VDI | D49: VDI-00 | E49: OCTET PLUS / ZVK | F49: ZVKCEFF1212K | G49: MO : Par liaison extérieure ≈ 60 m sous fourreau : 2,5 h (réf. ECLAIRION 2,5 h + 0,5 h pour ≤ 30 m, optimisé) ; test en ligne 32 | Fourniture Octet Plus devis DE044128 du 15/10/2026 (ZVK EasyLan, garantie système 25 ans ; baies LIEN'K), par liaison : câble Cat. 6A F/FTP ≈ 60 m + 2 noyaux + plastron + 2 cordons + quote-part platines = 48.71 €. Câble intérieur LSFROH : prévoir fourreau/protection pour les parcours extérieurs. Pose non incluse. | H49: u | I49: 30 | J49: 48.71 | K49: =J49*$I49 | L49: 2.5 | M49: =L49*$I49 | O49: =N49*$I49 | Q49: =P49*$I49 | R49: =$L49*$M$14+$N49*$O$14+$P49*$Q$14 | S49: =R49*$I49 | T49: =$S49+$K49 | U49: =HLOOKUP($C49,Recap_FCI!$K$9:$S$20,11,FALSE) | V49: =HLOOKUP($C49,Recap_FCI!$K$9:$S$20,12,FALSE) | W49: =$J49*$U49 | X49: =$R49*$V49 | Y49: =X49+W49 | Z49: =$W49*$I49 | AA49: =$X49*$I49 | AB49: =$Y49*$I49
...

Sheet CGV PROSYB
A2: CONDITIONS GENERALES DE VENTE Edition 01 2025
A4: 1. Définitions | C4: le Fournisseur pourra résilier le Contrat sans préavis par l’envoi d’une lettre RAR adressée au Client,
C5: sans préjudice d’une demande d’indemnisation.
A6: « Date d’établissement des prix » désigne la date d’établissement des prix mentionnée
A7: sur la proposition commerciale du Fournisseur ou à défaut, la date d’émission de cette | C7: 5. Interruption et Modification
A8: proposition commerciale ou à défaut, la date de la première signature des Conditions
A9: Particulières. | C9: 5.1 Le Fournisseur se réserve le droit d’interrompre la commercialisation, à tout
A10: « Client » désigne le co-contractant du Fournisseur dont les références sont précisées | C10: moment, de l’un ou de plusieurs de ses Livrables et des Prestations; une telle
A11: dans les Conditions Particulières. Si ces dernières désignent comme bénéficiaire des | C11: interruption ne remettant toutefois pas en cause la fourniture de Livrables et/ou
A12: Livrables et/ou Prestations une entité juridique autre que le signataire, le terme Client sera | C12: Prestations préalablement acceptés par les Parties.
A13: étendu à cette entité juridique. | C13: 5.2 Du fait de l’évolution rapide des technologies, le Fournisseur se réserve le droit de
A14: « Conditions Générales » désignent le présent document. | C14: fournir au Client des Livrables différents de ceux commandés à condition qu’une telle
A15: « Conditions Particulières » désignent le document signé par les Parties (ou à défaut la | C15: substitution ne conduise à aucune altération des qualités inhérentes au Livrable
A16: proposition du Fournisseur acceptée par le Client selon les stipulations des présentes) | C16: initialement prévues et sans que le Contrat ne puisse donner lieu à résolution ou à
A17: précisant notamment les Livrables, les prix et les Prestations éventuellement souscrites | C17: réfaction.
A18: par le Client.
A19: « Constructeurs » désignent le(s) fabricant(s) des Matériels et/ou le(s) éditeurs des | C19: 6. Propriété Intellectuelle
A20: Logiciels.
A21: « Contrat » désigne les Conditions Générales et les Conditions Particulières. | C21: 6.1 Tous plans, dessins, méthodes, concepts, savoir-faire, techniques, textes, schémas
A22: « Développement Spécifique » désigne tout développement logiciel réalisé par le | C22: et en général tous documents relatifs à la conception, à la construction, à l’exécution ou
A23: Fournisseur pour répondre à un besoin fonctionnel spécifique du Client lequel déclare | C23: mise en œuvre des Livrables, toutes mises à jour, copies de Livrables, ainsi que tous
A24: détenir les accords et droits nécessaires du titulaire d’un logiciel ou progiciel préexistant | C24: renseignements d’ordre technique ou commercial fournis à l’occasion de la proposition
A25: pour réaliser ledit développement. Les Développements Spécifiques sont régis par la | C25: commerciale et/ou du Contrat demeurent la propriété du Fournisseur et/ou de ses
A26: Licence d’Utilisation du Fournisseur en vigueur. | C26: Constructeurs et ne pourront être reproduits ou communiqués aux tiers sans l’accord
A27: « Equipement » désigne tout Matériel et/ou Logiciel acheté(s) par le Client auprès du | C27: préalable écrit du Fournisseur et/ou de ses Constructeurs.
A28: Fournisseur ainsi que leur documentation associée, tels que listés limitativement dans les | C28: 6.2 Tous droits de propriété intellectuelle attachés aux Livrables restent la propriété
A29: Conditions Particulières. | C29: entière et exclusive du Fournisseur et/ou des Constructeurs, le Client ne bénéficiant que
A30: « Fournisseur » désigne la Société dont les coordonnées sont précisées aux Conditions | C30: des droits concédés sur les dits Livrables au titre des licences accordées par le
A31: Particulières ou au Bon de Commande. Le Fournisseur peut être PROSYB ou l’une de ses sociétés | C31: Fournisseur et/ou les Constructeurs dont il déclare avoir pris connaissance et en
A32: Particulières ou au Bon de Commande. Le Fournisseur peut être PROSYB ou l’une de ses sociétés | B32: Installation CloudLink | C32: Fournisseur et/ou les Constructeurs dont il déclare avoir pris connaissance et en | F32: 1
A33: affiliées (« Société Affiliée » signifie toute entité juridique qui contrôle, est contrôlée ou est | C33: respecter l’intégralité des termes. En tout état de cause, le Client reconnaît que le
A34: sous le même contrôle qu’une des Parties au sens de l’article L.233-16 du Code de | C34: Fournisseur ne peut accorder plus de droits qu’il n’en a reçus du Constructeur.
A35: commerce.) | C35: Sous réserve de ses droits et de ceux des tiers qui lui sont octroyés dans les conditions
A36: « Livrable » désigne les Développements Spécifiques, les Equipements et les Modules | C36: strictes des licences concernées, le Fournisseur consentira au Client une licence non-
A37: Logiciels. | C37: exclusive d’utilisation des Livrables en France métropolitaine, selon leurs destinations,
A38: « Logiciel » désigne l’ensemble des programmes informatiques, procédés, règles de langage et la | C38: pour les seuls besoins personnels du Client et pour la durée spécifiée dans la licence
A39: documentation éventuelle, sous forme de code objet, relatifs au fonctionnement d’un ensemble | C39: concernée. Cette licence ne conférera pas au Client le droit:
A40: de traitement de données pour une machine, fournis sur une bande magnétique ou sur tout autre | C40: (i) de sous-licencier les Livrables;
A41: support de stockage présent ou à venir. | C41: (ii) de modifier ou de faire modifier par un tiers lesdits Livrables ;
A42: « Matériel » désigne l’intégralité des ensembles et sous-ensembles composés d’éléments | C42: (iii) de copier ou de reproduire les Livrables à l’exception d’une copie dite de
...

Sheet FAMILLE
A1: LOT FAM | B1: NOM FAMILLE
A2: AUT-00 | B2: Chemins de cables, Cablofil et accessoires
A3: AUT-10 | B3: Mise à la terre
A4: AUT-20 | B4: Etiquettage, repérage
A5: AUT-30 | B5: Consommables
A6: AUT-40 | B6: Boitiers alu, boitiers de sol
A7: AUT-50 | B7: Goulottes, moulures, plinthes électriques, tube IRO, Gaine ICT, boites de dérivation …
A8: AUT-60
A9: AUT-70
A10: AUT-80
A11: AUT-90
A12: VDI-00 | B12: Cables 4p
A13: VDI-10 | B13: Multipaire Téléphone
A14: VDI-20 | B14: Fibres Optiques Cables, connecteurs et accessoires
A15: VDI-30 | B15: Noyaux et accessoires de prise
A16: VDI-40 | B16: Platines 19"
A17: VDI-50 | B17: Baies, Coffrets, Fermes et accessoires
A18: VDI-60 | B18: Solution de Gestion de Câblage
A19: VDI-70 | B19: Cordons de brassage, jarretières optiques
A20: VDI-80
A21: VDI-90
A22: CFA-00 | B22: Câblage Cfa
A23: CFA-10 | B23: Equipements Contrôle d'accès
A24: CFA-20 | B24: Applications de Contrôle d'accès
A25: CFA-30 | B25: Equipements Vidéo Surveillance
A26: CFA-40 | B26: Applications de Vidéo Surveillance
A27: CFA-50 | B27: Equipements Détection Intrusion
A28: CFA-60 | B28: Applications et centrale de Détection Intrusion
A29: CFA-70 | B29: Equipements Visiophonie, Interphonie
A30: CFA-80 | B30: Applications de Visiophonie, Interphonie
A31: CFA-90 | B31: Solution de Téléphonie (téléphone, PABX, périphériques …)
A32: CFA-95 | B32: Réseau informatique (Switch, média converter, routeur …)
A33: CFA-99 | B33: Serveurs, PC, Consoles, écran, imprimantes
... A36: SSI-20 | B36: EXTINCTION INCENDIE
A37: SSI-30
A38: SSI-40
A39: SSI-50
A40: SSI-60
A41: SSI-70
A42: SSI-80
...

Sheet REF
A1: Répertoire outils FCI | B1: c:\calcul\FCI | C1: Nom Feuille Modèle Bordereau | E1: Nom du Tarif | F1: Chemin complet vers le Fichier Base Tarif | H1: Vendeur | I1: Opérationnels | J1: Agences | K1: Offres | L1: Technologies
A2: Fichier modèles bordereau | B2: FCI_BORDEREAUX_SPIE.xlsx
A3: Figer Prix de Vente | B3: FALSE | C3: VDI Tertiaire | E3: VDI FLOW BUSINESS | F3: S:\DASCIO\Dpt-SIO\Communs\TARIFS\Tarif_VDI_Flow Business.xlsm | H3: Woody SEALE | I3: Woody SEALE | K3: VENTES NEUVES ET INSTALLATION | L3: CABLAGE & INFRASTRUCTURES VDI
A4: Index Tarif | C4: VDI DataCenter | E4: VDI COMMSCOPE | F4: S:\DASCIO\Dpt-SIO\Communs\TARIFS\Tarif_VDI_Commscope.xlsm | H4: YANDJA Palou | I4: YANDJA Palou | K4: NEGOCE | L4: SALLES INFORMATIQUES / LOCAUX SECURISES (LTS)
A5: Modele SPIE | C5: SURETE | E5: VDI NEXANS | F5: S:\DASCIO\Dpt-SIO\Communs\TARIFS\Tarif_VDI_Nexans.xlsm | H5: Jean-Miche BARBIER | I5: Jean-Miche BARBIER | K5: ADJONCTIONS / TRAVAUX | L5: ENERGIE & CLIMATISATION
A6: Répertoire installation | B6: \\ce\dfs-FI07\NATIONAL\Data-FTP\Basefc\DCE | C6: CFO Tertiaire | K6: TRAVAUX SUPPLEMENTAIRES (SUR AFFAIRE) | L6: SURETE (CONTRÔLE D'ACCES, GTC)
A7: Fichier Revue | B7: REVUE_OFFRE.xlsm | C7: CFO DataCenter | K7: DCR (PTVX, DEPANNAGE, Prestations au Ticket) | L7: VIDEO-PROTECTION ET IMAGERIE
A8: Fichier FDC | B8: Fiche de compte.xlsm | C8: CVC Tertiaire | K8: DEPLOIEMENT INDUSTRIEL (POSTES DE TRAVAIL, HORS OPERATEURS)
A9: Fichier Para User | B9: C:\calcul\annuaire\para_user.xls | C9: CVC DataCenter | K9: PROJET CLIENT SOUS CONTRAT INFOGERANCE | L9: RESEAUX LOCAUX FILAIRES
A10: Nom du Refnoms | B10: c:\calcul\refnoms\Refnoms_AX_DASCIO.xls | K10: DCR CLIENT SOUS CONTRAT INFOGERANCE | L10: RESEAUX LOCAUX SANS FIL (WIFI)
A11: ID Vendeur | K11: DEPLOIEMENT INDUSTRIEL CLIENT SOUS CONTRAT INFOGERANCE | L11: RESEAUX ETENDUS (WAN, MAN, FH)
A12: Nom du Vendeur | K12: TRAVAUX CLIENT SOUS CONTRAT INFOGERANCE | L12: RESEAUX D'OPERATEURS
A13: Tél Vendeur | K13: GOUVERNANCE I.T. (ETUDES) | L13: CPE OPERATEURS
A14: Email Vendeur | K14: ASSISTANCE A LA MISE EN ŒUVRE | L14: RESEAU CISCO
A15: Initiales Vendeur | K15: GESTION ET OPTIMISATION (INVENTAIRE, AUDITS…) | L15: RESEAU AVAYA
A16: Agence AX | K16: CONSEIL CLIENT SOUS CONTRAT INFOGERANCE | L16: RESEAU HP
A17: Adresse Agence | B17: 53, Bd de Stalingrad | L17: RESEAUX INDUSTRIELS ET EMBARQUES
A18: CP Agence | B18: 92247 | K18: MAINTIEN EN CONDITION OPERATIONNELLE (M.C.O.)
A19: Ville Agence | B19: Malakoff Cedex | K19: INFOGERANCE D'INFRASTRUCTURES (SUR SITE) | L19: SECURITE DES INFRASTRUCTURES ET TERMINAUX
A20: Direction Activité | B20: Direction des Activités Public et Industrie | K20: INFOGERANCE D'INFRASTRUCTURES (A DISTANCE) | L20: SECURITE ET PERFORMANCE DES APPLICATIONS
A21: Société | B21: SPIE ICS | K21: INFOGERANCE UTILISATEURS (SUR SITE)
A22: SIRET | B22: SAS au capital de 16.240.000 euros - RCS NANTERRE - SIRET 319 060 075 00813 - APE 6202A | K22: SERVICES D'INFOGERANCE UTILISATEURS (A DISTANCE) | L22: RESEAUX IP DU DATACENTER
K23: READOSSEMENT SUR CONTRAT | L23: SERVEURS
K24: INFOGERANCE GLOBALE (SUR SITE) | L24: STOCKAGE, ARCHIVAGE, RESTAURATION
K25: INFOGERANCE GLOBALE (A DISTANCE) | L25: POSTES DE TRAVAIL & PERIPHERIQUES BUREAUTIQUES
K26: LOGISTIQUE REPARATION | L26: VIRTUALISATION (SERVEURS, POSTES DE TRAVAIL)
K27: INFOGERANCE D'INFRASTRUCTURES (ASSISTANCE TECHNIQUE) | L27: APPLICATIONS D'ENTREPRISE (MESSAGERIE, ANNUAIRE…)
K28: INFOGERANCE UTILISATEURS (ASSISTANCE TECHNIQUE) | L28: APPLICATIONS D'ENTREPRISE (METIERS…)
K29: INFOGERANCE GLOBALE (ASSISTANCE TECHNIQUE)
A30: CGV | B30: CGV Multisociétés.pdf | L30: INFRASTRUCTURES DE TELEPHONIE (PABX, TOIP)
A31: Fichier Confo FCI | B31: FCI_CONFO.xlsm | K31: LIENS OPERATEURS VOIX (SC) | L31: VOIX AASTRA
A32: Manuel utilisation | B32: C:\calcul\FCI\Presentation_FCI.pdf | K32: LIENS OPERATEURS DATA (SC) | L32: VOIX CISCO
K33: DEPLOIEMENTS OPERATEURS SFR | L33: VOIX MITEL
K34: SERVICES MANAGES | L34: VOIX AVAYA
K35: SERVICES HEBERGES | L35: VOIX UNIFY
K36: SERVICES CLOUD | L36: TERMINAUX FIXES
K37: DEPLOIEMENTS OPERATEURS AUTRES | L37: TERMINAUX MOBILES & OUTILS DE NOMADISME
L38: OUTILS D'ADMIN. VOIX & TAXATION
K40: REVENUS OPERATEURS | L40: APPLI COMM UNIFIEE AASTRA
K41: REVISION DE PRIX & AUTRES REVENUS FINANCIERS | L41: APPLI COMM UNIFIEE CISCO
...

Sheet Revue Initialisation
E1: REVUE D'INITIALISATION PROJET
E2: Passation Commerce → Production — à compléter à la commande
A4: INFORMATIONS GÉNÉRALES DU PROJET
A5: Client | B5: =IF(Recap_FCI!C2="","",Recap_FCI!C2) -> Client | E5: Nom du projet (Affaire) | F5: =IF(Recap_FCI!C3="","",Recap_FCI!C3) -> Affaire | I5: Référence FCI / Axonaut | J5: À compléter
A6: Site | B6: =IF(Recap_FCI!C4="","",Recap_FCI!C4) | E6: Adresse chantier | F6: =IF(Recap_FCI!C5="","",Recap_FCI!C5) | I6: Type de bâtiment | J6: À compléter
A7: Technologie | B7: =IF(Recap_FCI!C6="","",Recap_FCI!C6) | E7: Offre | F7: =IF(Recap_FCI!C7="","",Recap_FCI!C7) | I7: N° Offre | J7: =IF(Recap_FCI!G2="","",Recap_FCI!G2)
A8: Phase projet | B8: À compléter | E8: Date de passation Commerce→Prod | I8: N° Commande client | J8: À compléter
A10: CONTACTS & INTERVENANTS
A11: Client Preneur | B11: =IF(Recap_FCI!L2="","",Recap_FCI!L2) -> Client Preneur : | E11: Maîtrise d'Ouvrage (MOA) | F11: =IF(Recap_FCI!L3="","",Recap_FCI!L3) -> Maitrise d'Ouvrage : | I11: Contact client (nom / tél / mail) | J11: À compléter
A12: Aménageur / BET / AMOA | B12: =IF(Recap_FCI!L4="","",Recap_FCI!L4) -> Aménageur / BET / AMOA : | E12: Maîtrise d'Œuvre (MOE) | F12: =IF(Recap_FCI!L5="","",Recap_FCI!L5) -> Maitrise d'Œuvre : | I12: Entrepreneur Principal | J12: =IF(Recap_FCI!L6="","",Recap_FCI!L6) -> Entrepreneur Principal :
A13: Architecte | B13: =IF(Recap_FCI!G3="","",Recap_FCI!G3) -> Woody SEALE | E13: BET | F13: =IF(Recap_FCI!G6="","",Recap_FCI!G6) | I13: Agence PROSYB | J13: =IF(Recap_FCI!G5="","",Recap_FCI!G5)
A15: ÉQUIPE PROJET PROSYB
A16: Responsable commercial / Ingénieur Affaires | B16: =IF(Recap_FCI!G4="","",Recap_FCI!G4) -> Woody SEALE | E16: Chargé d'affaire | F16: À compléter | I16: Conducteur de travaux pressenti | J16: À compléter
A17: Chef de chantier pressenti | B17: À compléter | E17: BET impliqué | F17: À compléter | I17: Heures internes prévues | J17: À compléter
A19: OBJECTIFS & ENJEUX
A20: Objectif principal du projet | C20: À compléter
A21: Contexte du projet | C21: À compléter
A22: Points forts du dossier | C22: À compléter
A23: Risques identifiés | C23: À compléter
A24: Alliés du projet | C24: À compléter
A25: Freins ou ennemis potentiels | C25: À compléter
A27: PLANNING PRÉVISIONNEL
A28: Date réception AO | B28: =IF(Recap_FCI!I2="","",Recap_FCI!I2) -> Date réception AO : | D28: Date revue offre | E28: =IF(Recap_FCI!I3="","",Recap_FCI!I3) -> Date Revue Offre : | G28: Date remise offre | H28: =IF(Recap_FCI!I4="","",Recap_FCI!I4) -> Date Remise Offre : | J28: Date soutenance | K28: =IF(Recap_FCI!I5="","",Recap_FCI!I5) -> Date Soutenance :
A29: Date décision | B29: =IF(Recap_FCI!I6="","",Recap_FCI!I6) -> Date Décision : | D29: Date début projet | E29: =IF(Recap_FCI!I7="","",Recap_FCI!I7) -> Date Début Projet : | G29: Début intervention prévue | J29: Fin estimée
A30: Délai global | B30: À compléter | D30: Date de MES promise | E30: =IF(Recap_FCI!G7="","",Recap_FCI!G7) | G30: Contraintes spécifiques | I30: À compléter
A32: CONDITIONS CONTRACTUELLES & FINANCIÈRES
A33: Conditions de règlement | B33: À compléter | E33: Retenue de garantie | F33: À compléter | I33: Pénalités de retard | J33: À compléter
A34: Modalités de facturation / échéancier | B34: À compléter | E34: Révision de prix | F34: À compléter | I34: Assurance décennale requise | J34: À compléter
A36: BUDGET & RESSOURCES
A37: Budget total vendu (HT) | B37: =IF(Recap_FCI!F13="","",Recap_FCI!F13) -> 0 | D37: Marge brute cible | E37: =IF(Recap_FCI!G15="","",Recap_FCI!G15) -> 0 | G37: Budget Matériel | H37: =IF(Recap_FCI!J13="","",Recap_FCI!J13) -> 0 | J37: Budget Main d'Œuvre | K37: =IF(Recap_FCI!I13="","",Recap_FCI!I13) -> 0
A38: Budget Sous-traitance (SSTT) | B38: =SUM(E42:E50) -> 0 | D38: Heures prévues internes | E38: À compléter | G38: Fournitures principales | I38: À compléter
A40: SOUS-TRAITANTS PRESSENTIS
A41: Sous-traitant | C41: Rôle | E41: Budget alloué | G41: Contact / Tél | I41: Devis reçu | K41: Contrat signé
I42: ☐ | K42: ☐
I43: ☐ | K43: ☐
I44: ☐ | K44: ☐
I45: ☐ | K45: ☐
I46: ☐ | K46: ☐
I47: ☐ | K47: ☐
I48: ☐ | K48: ☐
...
