Workbook

Sheet Récap
A1: Récap FCI v6 — KHAZNA ORY01 — courants faibles base vie & chantier — 16/10/2026 (mise à jour GTB AETHERYS)
A3: Lot | B3: Désignation | C3: Fournitures PR | D3: MO PR | E3: Total PR | F3: Total PV HT | G3: Marge brute | H3: Taux / PV
A4: 4 | B4: Informatique, audiovisuel, affichage | C4: =SUMPRODUCT(('Détail chiffrage'!B2:B61="4")*('Détail chiffrage'!F2:F61+'Détail chiffrage'!G2:G61)*'Détail chiffrage'!E2:E61) | D4: =SUMPRODUCT(('Détail chiffrage'!B2:B61="4")*'Détail chiffrage'!L2:L61*'Détail chiffrage'!E2:E61) | E4: =C4+D4 | F4: =FCI!F51 | G4: =F4-E4 | H4: =IF(F4=0,0,G4/F4)
A5: 5 | B5: Sécurité SSI | C5: =SUMPRODUCT(('Détail chiffrage'!B2:B61="5")*('Détail chiffrage'!F2:F61+'Détail chiffrage'!G2:G61)*'Détail chiffrage'!E2:E61) | D5: =SUMPRODUCT(('Détail chiffrage'!B2:B61="5")*'Détail chiffrage'!L2:L61*'Détail chiffrage'!E2:E61) | E5: =C5+D5 | F5: =FCI!F73 | G5: =F5-E5 | H5: =IF(F5=0,0,G5/F5)
A6: 6 | B6: Vidéosurveillance | C6: =SUMPRODUCT(('Détail chiffrage'!B2:B61="6")*('Détail chiffrage'!F2:F61+'Détail chiffrage'!G2:G61)*'Détail chiffrage'!E2:E61) | D6: =SUMPRODUCT(('Détail chiffrage'!B2:B61="6")*'Détail chiffrage'!L2:L61*'Détail chiffrage'!E2:E61) | E6: =C6+D6 | F6: =FCI!F83 | G6: =F6-E6 | H6: =IF(F6=0,0,G6/F6)
A7: 7 | B7: GTB / GTE (offre AETHERYS 16/10) | C7: =SUMPRODUCT(('Détail chiffrage'!B2:B61="7")*('Détail chiffrage'!F2:F61+'Détail chiffrage'!G2:G61)*'Détail chiffrage'!E2:E61) | D7: =SUMPRODUCT(('Détail chiffrage'!B2:B61="7")*'Détail chiffrage'!L2:L61*'Détail chiffrage'!E2:E61) | E7: =C7+D7 | F7: =FCI!F93 | G7: =F7-E7 | H7: =IF(F7=0,0,G7/F7)
B8: TOTAL | C8: =SUM(C4:C7) | D8: =SUM(D4:D7) | E8: =SUM(E4:E7) | F8: =SUM(F4:F7) | G8: =SUM(G4:G7) | H8: =G8/F8
A10: Hors FCI : études EXE.CFA (DPGF §2 « Architecture IT & audiovisuel »), part CFA de la maintenance 28 mois et permanence 24/7 (DPGF §8), encadrement, déplacements, nacelle.

Sheet FCI
A1: KHAZNA ORY01 — Lot courants faibles base vie & chantier — FCI PROSYB v6 (DPGF FR02201-ENG-ELEC-OTH-1029-01, lots 4 à 7)
A2: Prix de vente HT. Lignes « Hors lot » / « LOT GC » non chiffrées. Cellules jaunes du détail = fournitures estimatives sans devis.
A3: N°/Lot | B3: DESIGNATION | C3: U | D3: Qt. | E3: P.U. (€) | F3: P.T. (€) | G3: COMMENTAIRES / SOURCE
A4: 4 | B4: INFORMATIQUE & AUDIOVISUEL & AFFICHAGES LED
A5: 4.1 | B5: Phase 2 (2 mois)
B6: Informatique cœur de réseau
B7: Fourniture, pose et raccordement répartiteur informatique principal dans poste énergie Hub 1, incluant switch PoE | C7: Ens | D7: 1 | E7: ='Détail chiffrage'!O2 | F7: =D7*E7 | G7: ='Détail chiffrage'!R2
B8: Fourniture, pose et raccordement répartiteur informatique principal dans poste énergie Hub 2, incluant switch PoE | C8: Ens | D8: 1 | E8: ='Détail chiffrage'!O3 | F8: =D8*E8 | G8: ='Détail chiffrage'!R3
B9: Fourniture, pose et raccordement répartiteur informatique secondaire Est 1 incluant switch PoE | C9: Ens | D9: 1 | E9: ='Détail chiffrage'!O4 | F9: =D9*E9 | G9: ='Détail chiffrage'!R4
B10: Fourniture, pose et raccordement répartiteur informatique secondaire Est 2 incluant switch PoE | C10: Ens | D10: 1 | E10: ='Détail chiffrage'!O5 | F10: =D10*E10 | G10: ='Détail chiffrage'!R5
B11: Fourniture, pose et raccordement répartiteur informatique secondaire Est 3 incluant switch PoE | C11: Ens | D11: 1 | E11: ='Détail chiffrage'!O6 | F11: =D11*E11 | G11: ='Détail chiffrage'!R6
B12: Fourniture, pose et raccordement répartiteur informatique secondaire Ouest 1 incluant switch PoE | C12: Ens | D12: 1 | E12: ='Détail chiffrage'!O7 | F12: =D12*E12 | G12: ='Détail chiffrage'!R7
B13: Fourniture, pose et raccordement répartiteur informatique secondaire Ouest 2 incluant switch PoE | C13: Ens | D13: 1 | E13: ='Détail chiffrage'!O8 | F13: =D13*E13 | G13: ='Détail chiffrage'!R8
B14: Fourniture, pose et raccordement boucle fibre OS2 12 brins autocicatrisante depuis le répartiteur principal poste énergie Hub 1 vers répartiteurs secondaires Est 1, Est 2, Ouest 1, Ouest 2 et Ouest 3 | C14: Ens | D14: 1 | E14: ='Détail chiffrage'!O9 | F14: =D14*E14 | G14: ='Détail chiffrage'!R9
B15: Fourniture, pose et raccordement liaison fibre OS2 12 brins autocicatrisante depuis le répartiteur principal poste énergie Hub 1 vers le répartiteur princiapl Hub 2 | C15: Ens | D15: 1 | E15: ='Détail chiffrage'!O10 | F15: =D15*E15 | G15: ='Détail chiffrage'!R10
B16: Paramétrage équipements informatiques | C16: Ens | D16: 1 | E16: ='Détail chiffrage'!O11 | F16: =D16*E16 | G16: ='Détail chiffrage'!R11
B17: Test de réfléctométrie | C17: Ens | D17: 1 | E17: ='Détail chiffrage'!O12 | F17: =D17*E17 | G17: ='Détail chiffrage'!R12
B18: Informatique îlots 1 et 2
B19: Fourniture, pose et raccordement liaison cuivre répartiteur informatique principal vers équipements (postes de travail CAD + bornes WiFi), 12 prises RJ45 par îlot, soit 24 prises RJ45 au total | C19: Ens | D19: 1 | E19: ='Détail chiffrage'!O13 | F19: =D19*E19 | G19: ='Détail chiffrage'!R13
B20: Pose et raccordement borne WiFi | C20: U | D20: 4 | E20: ='Détail chiffrage'!O14 | F20: =D20*E20 | G20: ='Détail chiffrage'!R14
B21: Fourniture, pose et raccordement équipements audiovisuel salle de réunion (Un écran 85" par salle de réunion, avec enceinte caméra combinée + kit 5x micros déportés connectés) | C21: U | D21: 3 | E21: ='Détail chiffrage'!O15 | F21: =D21*E21 | G21: ='Détail chiffrage'!R15
B22: Recettage cuivre | C22: Ens | D22: 1 | E22: ='Détail chiffrage'!O16 | F22: =D22*E22 | G22: ='Détail chiffrage'!R16
A23: 4.1 | B23: Phase 3 (5 mois)
B24: Informatique cœur de réseau
B25: Sans objet | C25: Ens | D25: 1 | E25: ='Détail chiffrage'!O17 | F25: =D25*E25 | G25: ='Détail chiffrage'!R17
B26: Informatique îlots 3 à 10
B27: Fourniture, pose et raccordement liaisons cuivre répartiteur informatique principal vers équipements (postes de travail CAD + bornes WiFi), 12 prises RJ45 par îlot, soit 96 prises RJ45 au total | C27: Ens | D27: 1 | E27: ='Détail chiffrage'!O18 | F27: =D27*E27 | G27: ='Détail chiffrage'!R18
B28: Fourniture, pose et raccordement borne WiFi | C28: U | D28: 20 | E28: ='Détail chiffrage'!O19 | F28: =D28*E28 | G28: ='Détail chiffrage'!R19
B29: Fourniture, pose et raccordement équipements audiovisuel salle de réunion (Un écran 85" par salle de réunion, avec enceinte caméra combinée + kit 5x micros déportés connectés) | C29: U | D29: 7 | E29: ='Détail chiffrage'!O20 | F29: =D29*E29 | G29: ='Détail chiffrage'!R20
B30: Recettage cuivre | C30: Ens | D30: 1 | E30: ='Détail chiffrage'!O21 | F30: =D30*E30 | G30: ='Détail chiffrage'!R21
B31: Informatique chantier
B32: Fourniture, pose et raccordement répartiteur secondaire bâtiments annexes | C32: U | D32: 2 | E32: ='Détail chiffrage'!O22 | F32: =D32*E32 | G32: ='Détail chiffrage'!R22
B33: Fourniture, pose et raccordement liaisons RJ45 CAT6A F/STP bâtiments techniques & extérieurs | C33: U | D33: 30 | E33: ='Détail chiffrage'!O23 | F33: =D33*E33 | G33: ='Détail chiffrage'!R23
B34: Recettage cuivre | C34: Ens | D34: 1 | E34: ='Détail chiffrage'!O24 | F34: =D34*E34 | G34: ='Détail chiffrage'!R24
B35: Afficheurs chantier
B36: Fourniture, pose et raccordement afficheurs chantier extérieur + Support | C36: U | D36: 6 | E36: ='Détail chiffrage'!O25 | F36: =D36*E36 | G36: ='Détail chiffrage'!R25
B37: Paramétrage | C37: Ens | D37: 1 | E37: ='Détail chiffrage'!O26 | F37: =D37*E37 | G37: ='Détail chiffrage'!R26
A38: 4.1 | B38: Phase 4 (17 mois)
B39: Informatique cœur de réseau
B40: Fourniture, pose et raccordement répartiteur informatique principal dans poste énergie Hub 3, incluant switch PoE | C40: Ens | D40: 1 | E40: ='Détail chiffrage'!O27 | F40: =D40*E40 | G40: ='Détail chiffrage'!R27
...

Sheet Paramètres
A1: Paramètre | B1: Valeur | C1: Commentaire
A2: Taux monteur €/h | B2: 40
A3: Taux technicien CFA €/h | B3: 60
A4: Taux technicien SSI €/h | B4: 62
A5: Taux BE €/h | B5: 75
A6: Coef k VDI/AV/vidéo/GTB | B6: 1.444444 | C6: PR × 1,04 / (1 − 20 % − 8 %)
A7: Coef k SSI | B7: 1.350649 | C7: PR × 1,04 / (1 − 15 % − 8 %)

Sheet Détail chiffrage
A1: Ligne DPGF | B1: Lot | C1: Désignation | D1: U | E1: Qté | F1: Fourn. devis PR/u | G1: Fourn. ajoutée PR/u (estimatif) | H1: h Monteur/u | I1: h Tech CFA/u | J1: h Tech SSI/u | K1: h BE/u | L1: MO PR/u | M1: PR/u | N1: k | O1: PV/u | P1: PV total | Q1: PR total | R1: Source fournisseur | S1: Hypothèses MO / fournitures ajoutées
A2: 4 | B2: 4 | C2: Fourniture, pose et raccordement répartiteur informatique principal dans poste énergie Hub 1, incluant switch PoE | D2: Ens | E2: 1 | F2: 1420.88 | G2: 0 | H2: 0 | I2: 5 | J2: 0 | K2: 0 | L2: =H2*Paramètres!$B$2+I2*Paramètres!$B$3+J2*Paramètres!$B$4+K2*Paramètres!$B$5 | M2: =F2+G2+L2 | N2: =Paramètres!$B$6 | O2: =ROUND(M2*N2,2) | P2: =O2*E2 | Q2: =M2*E2 | R2: Octet Plus DE044128 du 15/10/2026 : baie 42U BAI4288CN 615,40 + bandeau 8PC 19,45 ; CCF/Sonepar 313371 du 12/10/2026 : switch L3 S57244-B0 786,03 | S2: Pose baie + switch L3 (5 h tech)
A3: 5 | B3: 4 | C3: Fourniture, pose et raccordement répartiteur informatique principal dans poste énergie Hub 2, incluant switch PoE | D3: Ens | E3: 1 | F3: 634.85 | G3: 0 | H3: 0 | I3: 5 | J3: 0 | K3: 0 | L3: =H3*Paramètres!$B$2+I3*Paramètres!$B$3+J3*Paramètres!$B$4+K3*Paramètres!$B$5 | M3: =F3+G3+L3 | N3: =Paramètres!$B$6 | O3: =ROUND(M3*N3,2) | P3: =O3*E3 | Q3: =M3*E3 | R3: Octet Plus DE044128 du 15/10/2026 : baie 42U + bandeau. Switch fourni par EXYTE | S3: Pose baie + switch EXYTE (5 h)
A4: 6 | B4: 4 | C4: Fourniture, pose et raccordement répartiteur informatique secondaire Est 1 incluant switch PoE | D4: Ens | E4: 1 | F4: 0 | G4: 0 | H4: 0 | I4: 2 | J4: 0 | K4: 0 | L4: =H4*Paramètres!$B$2+I4*Paramètres!$B$3+J4*Paramètres!$B$4+K4*Paramètres!$B$5 | M4: =F4+G4+L4 | N4: =Paramètres!$B$6 | O4: =ROUND(M4*N4,2) | P4: =O4*E4 | Q4: =M4*E4 | R4: Coffret IP55 fourni/posé SPIE ; switch EXYTE ; tiroir et panneau comptés dans lignes fibre/cuivre | S4: Intégration dans coffret SPIE 2 h
A5: 7 | B5: 4 | C5: Fourniture, pose et raccordement répartiteur informatique secondaire Est 2 incluant switch PoE | D5: Ens | E5: 1 | F5: 0 | G5: 0 | H5: 0 | I5: 2 | J5: 0 | K5: 0 | L5: =H5*Paramètres!$B$2+I5*Paramètres!$B$3+J5*Paramètres!$B$4+K5*Paramètres!$B$5 | M5: =F5+G5+L5 | N5: =Paramètres!$B$6 | O5: =ROUND(M5*N5,2) | P5: =O5*E5 | Q5: =M5*E5 | R5: Idem Est 1 | S5: Idem
A6: 8 | B6: 4 | C6: Fourniture, pose et raccordement répartiteur informatique secondaire Est 3 incluant switch PoE | D6: Ens | E6: 1 | F6: 0 | G6: 0 | H6: 0 | I6: 2 | J6: 0 | K6: 0 | L6: =H6*Paramètres!$B$2+I6*Paramètres!$B$3+J6*Paramètres!$B$4+K6*Paramètres!$B$5 | M6: =F6+G6+L6 | N6: =Paramètres!$B$6 | O6: =ROUND(M6*N6,2) | P6: =O6*E6 | Q6: =M6*E6 | R6: Idem Est 1 | S6: Idem
A7: 9 | B7: 4 | C7: Fourniture, pose et raccordement répartiteur informatique secondaire Ouest 1 incluant switch PoE | D7: Ens | E7: 1 | F7: 0 | G7: 0 | H7: 0 | I7: 2 | J7: 0 | K7: 0 | L7: =H7*Paramètres!$B$2+I7*Paramètres!$B$3+J7*Paramètres!$B$4+K7*Paramètres!$B$5 | M7: =F7+G7+L7 | N7: =Paramètres!$B$6 | O7: =ROUND(M7*N7,2) | P7: =O7*E7 | Q7: =M7*E7 | R7: Idem Est 1 | S7: Idem
A8: 10 | B8: 4 | C8: Fourniture, pose et raccordement répartiteur informatique secondaire Ouest 2 incluant switch PoE | D8: Ens | E8: 1 | F8: 0 | G8: 0 | H8: 0 | I8: 2 | J8: 0 | K8: 0 | L8: =H8*Paramètres!$B$2+I8*Paramètres!$B$3+J8*Paramètres!$B$4+K8*Paramètres!$B$5 | M8: =F8+G8+L8 | N8: =Paramètres!$B$6 | O8: =ROUND(M8*N8,2) | P8: =O8*E8 | Q8: =M8*E8 | R8: Idem Est 1 | S8: Idem
A9: 11 | B9: 4 | C9: Fourniture, pose et raccordement boucle fibre OS2 12 brins autocicatrisante depuis le répartiteur principal poste énergie Hub 1 vers répartiteurs secondaires Est 1, Est 2, Ouest 1, Ouest 2 et Ouest 3 | D9: Ens | E9: 1 | F9: 7094.92 | G9: 0 | H9: 72.5 | I9: 0 | J9: 0 | K9: 0 | L9: =H9*Paramètres!$B$2+I9*Paramètres!$B$3+J9*Paramètres!$B$4+K9*Paramètres!$B$5 | M9: =F9+G9+L9 | N9: =Paramètres!$B$6 | O9: =ROUND(M9*N9,2) | P9: =O9*E9 | Q9: =M9*E9 | R9: Octet Plus DE044128 du 15/10/2026 : OS2 12 brins ZVKLUZB12OS2 ≈2 900 ml (3 728,57) + 6 tronçons tiroirs/fusion/photométrie/jarretières (561,06 × 6) | S9: Tirage 2,5 h/100 ml ; fusion et tests Octet Plus
A10: 12 | B10: 4 | C10: Fourniture, pose et raccordement liaison fibre OS2 12 brins autocicatrisante depuis le répartiteur principal poste énergie Hub 1 vers le répartiteur princiapl Hub 2 | D10: Ens | E10: 1 | F10: 1139.63 | G10: 0 | H10: 11.25 | I10: 0 | J10: 0 | K10: 0 | L10: =H10*Paramètres!$B$2+I10*Paramètres!$B$3+J10*Paramètres!$B$4+K10*Paramètres!$B$5 | M10: =F10+G10+L10 | N10: =Paramètres!$B$6 | O10: =ROUND(M10*N10,2) | P10: =O10*E10 | Q10: =M10*E10 | R10: Octet Plus DE044128 du 15/10/2026 : OS2 ≈450 ml 578,57 + tronçon 561,06 | S10: Tirage 450 ml
A11: 13 | B11: 4 | C11: Paramétrage équipements informatiques | D11: Ens | E11: 1 | F11: 0 | G11: 0 | H11: 0 | I11: 20 | J11: 0 | K11: 16 | L11: =H11*Paramètres!$B$2+I11*Paramètres!$B$3+J11*Paramètres!$B$4+K11*Paramètres!$B$5 | M11: =F11+G11+L11 | N11: =Paramètres!$B$6 | O11: =ROUND(M11*N11,2) | P11: =O11*E11 | Q11: =M11*E11 | R11: MO PROSYB | S11: Paramétrage cœurs + 5 secondaires + ERPS/VLAN ; BE adressage, synoptiques, DOE
A12: 14 | B12: 4 | C12: Test de réfléctométrie | D12: Ens | E12: 1 | F12: 0 | G12: 0 | H12: 0 | I12: 0 | J12: 0 | K12: 0 | L12: =H12*Paramètres!$B$2+I12*Paramètres!$B$3+J12*Paramètres!$B$4+K12*Paramètres!$B$5 | M12: =F12+G12+L12 | N12: =Paramètres!$B$6 | O12: =ROUND(M12*N12,2) | P12: =O12*E12 | Q12: =M12*E12 | R12: Incluse lignes fibre (Octet Plus DE044128 du 15/10/2026 : test 1310/1550 nm 2 sens + photométrie Fluke) | S12: Sans MO
A13: 16 | B13: 4 | C13: Fourniture, pose et raccordement liaison cuivre répartiteur informatique principal vers équipements (postes de travail CAD + bornes WiFi), 12 prises RJ45 par îlot, soit 24 prises RJ45 au total | D13: Ens | E13: 1 | F13: 770.76 | G13: 0 | H13: 28.8 | I13: 0 | J13: 0 | K13: 0 | L13: =H13*Paramètres!$B$2+I13*Paramètres!$B$3+J13*Paramètres!$B$4+K13*Paramètres!$B$5 | M13: =F13+G13+L13 | N13: =Paramètres!$B$6 | O13: =ROUND(M13*N13,2) | P13: =O13*E13 | Q13: =M13*E13 | R13: Octet Plus DE044128 du 15/10/2026 : 24 liens Cat6A F/FTP ZVKCEFF1212K ≈35 m + noyaux fixLink + plastrons + cordons — POSE NON INCLUSE | S13: 24 liens × 1,2 h
... A16: 19 | B16: 4 | C16: Recettage cuivre | D16: Ens | E16: 1 | F16: 0 | G16: 0 | H16: 0 | I16: 3.4 | J16: 0 | K16: 0 | L16: =H16*Paramètres!$B$2+I16*Paramètres!$B$3+J16*Paramètres!$B$4+K16*Paramètres!$B$5 | M16: =F16+G16+L16 | N16: =Paramètres!$B$6 | O16: =ROUND(M16*N16,2) | P16: =O16*E16 | Q16: =M16*E16 | R16: Certification classe EA PROSYB (non chiffrée Octet Plus) | S16: 24 liens × 0,1 h + rapport
A17: 22 | B17: 4 | C17: Sans objet | D17: Ens | E17: 1 | F17: 0 | G17: 0 | H17: 0 | I17: 0 | J17: 0 | K17: 0 | L17: =H17*Paramètres!$B$2+I17*Paramètres!$B$3+J17*Paramètres!$B$4+K17*Paramètres!$B$5 | M17: =F17+G17+L17 | N17: =Paramètres!$B$6 | O17: =ROUND(M17*N17,2) | P17: =O17*E17 | Q17: =M17*E17 | R17: Sans objet DPGF
A18: 24 | B18: 4 | C18: Fourniture, pose et raccordement liaisons cuivre répartiteur informatique principal vers équipements (postes de travail CAD + bornes WiFi), 12 prises RJ45 par îlot, soit 96 prises RJ45 au total | D18: Ens | E18: 1 | F18: 3083.05 | G18: 0 | H18: 115.2 | I18: 0 | J18: 0 | K18: 0 | L18: =H18*Paramètres!$B$2+I18*Paramètres!$B$3+J18*Paramètres!$B$4+K18*Paramètres!$B$5 | M18: =F18+G18+L18 | N18: =Paramètres!$B$6 | O18: =ROUND(M18*N18,2) | P18: =O18*E18 | Q18: =M18*E18 | R18: Octet Plus DE044128 du 15/10/2026 : 96 liens Cat6A ≈35 m — pose non incluse | S18: 96 × 1,2 h
A19: 25 | B19: 4 | C19: Fourniture, pose et raccordement borne WiFi | D19: U | E19: 20 | F19: 0 | G19: 160 | H19: 0.75 | I19: 0.25 | J19: 0 | K19: 0 | L19: =H19*Paramètres!$B$2+I19*Paramètres!$B$3+J19*Paramètres!$B$4+K19*Paramètres!$B$5 | M19: =F19+G19+L19 | N19: =Paramètres!$B$6 | O19: =ROUND(M19*N19,2) | P19: =O19*E19 | Q19: =M19*E19 | R19: Borne Wi-Fi 6 PoE type Ubiquiti U6 Pro 160 € (ESTIMATIF, pas de devis) | S19: 0,75 h + 0,25 h
A20: 26 | B20: 4 | C20: Fourniture, pose et raccordement équipements audiovisuel salle de réunion (Un écran 85" par salle de réunion, avec enceinte caméra combinée + kit 5x micros déportés connectés) | D20: U | E20: 7 | F20: 8102.65 | G20: 756 | H20: 3 | I20: 3 | J20: 0 | K20: 0 | L20: =H20*Paramètres!$B$2+I20*Paramètres!$B$3+J20*Paramètres!$B$4+K20*Paramètres!$B$5 | M20: =F20+G20+L20 | N20: =Paramètres!$B$6 | O20: =ROUND(M20*N20,2) | P20: =O20*E20 | Q20: =M20*E20 | R20: Sonepar AV 0014640130 du 16/10/2026 : idem P2 | S20: Idem P2
A21: 27 | B21: 4 | C21: Recettage cuivre | D21: Ens | E21: 1 | F21: 0 | G21: 0 | H21: 0 | I21: 10.6 | J21: 0 | K21: 0 | L21: =H21*Paramètres!$B$2+I21*Paramètres!$B$3+J21*Paramètres!$B$4+K21*Paramètres!$B$5 | M21: =F21+G21+L21 | N21: =Paramètres!$B$6 | O21: =ROUND(M21*N21,2) | P21: =O21*E21 | Q21: =M21*E21 | R21: Certification PROSYB | S21: 96 × 0,1 h + rapport
A22: 29 | B22: 4 | C22: Fourniture, pose et raccordement répartiteur secondaire bâtiments annexes | D22: U | E22: 2 | F22: 753.92 | G22: 0 | H22: 3.75 | I22: 2 | J22: 0 | K22: 0 | L22: =H22*Paramètres!$B$2+I22*Paramètres!$B$3+J22*Paramètres!$B$4+K22*Paramètres!$B$5 | M22: =F22+G22+L22 | N22: =Paramètres!$B$6 | O22: =ROUND(M22*N22,2) | P22: =O22*E22 | Q22: =M22*E22 | R22: Octet Plus DE044128 du 15/10/2026 : OS2 ≈150 ml + tronçon ; coffret SPIE ; switch EXYTE | S22: Tirage 150 ml + intégration 2 h
A23: 30 | B23: 4 | C23: Fourniture, pose et raccordement liaisons RJ45 CAT6A F/STP bâtiments techniques & extérieurs | D23: U | E23: 30 | F23: 48.71 | G23: 0 | H23: 2.5 | I23: 0 | J23: 0 | K23: 0 | L23: =H23*Paramètres!$B$2+I23*Paramètres!$B$3+J23*Paramètres!$B$4+K23*Paramètres!$B$5 | M23: =F23+G23+L23 | N23: =Paramètres!$B$6 | O23: =ROUND(M23*N23,2) | P23: =O23*E23 | Q23: =M23*E23 | R23: Octet Plus DE044128 du 15/10/2026 : Cat6A ≈60 m + noyaux + plastron + cordons (câble intérieur LSFROH → fourreau obligatoire) | S23: 2,5 h / liaison
A24: 31 | B24: 4 | C24: Recettage cuivre | D24: Ens | E24: 1 | F24: 0 | G24: 0 | H24: 0 | I24: 4.5 | J24: 0 | K24: 0 | L24: =H24*Paramètres!$B$2+I24*Paramètres!$B$3+J24*Paramètres!$B$4+K24*Paramètres!$B$5 | M24: =F24+G24+L24 | N24: =Paramètres!$B$6 | O24: =ROUND(M24*N24,2) | P24: =O24*E24 | Q24: =M24*E24 | R24: Certification PROSYB | S24: 30 × 0,15 h
A25: 33 | B25: 4 | C25: Fourniture, pose et raccordement afficheurs chantier extérieur + Support | D25: U | E25: 6 | F25: 4852.81 | G25: 775 | H25: 6 | I25: 1.5 | J25: 0 | K25: 0 | L25: =H25*Paramètres!$B$2+I25*Paramètres!$B$3+J25*Paramètres!$B$4+K25*Paramètres!$B$5 | M25: =F25+G25+L25 | N25: =Paramètres!$B$6 | O25: =ROUND(M25*N25,2) | P25: =O25*E25 | Q25: =M25*E25 | R25: Sonepar AV 0014640130 du 16/10/2026 : Samsung OHDX 55" 3 752 + StiX 450 + licence 450 + switch PoE 164,19 + HDMI 11,58 + D3E/port 25,04 — SUPPORTS NON CHIFFRÉS | S25: Supports estimatifs : 3 bras antivol 250 € + 3 totems ERARD ≈1 300 € → moy. 775 €/u
A26: 34 | B26: 4 | C26: Paramétrage | D26: Ens | E26: 1 | F26: 0 | G26: 1100 | H26: 0 | I26: 16 | J26: 0 | K26: 12 | L26: =H26*Paramètres!$B$2+I26*Paramètres!$B$3+J26*Paramètres!$B$4+K26*Paramètres!$B$5 | M26: =F26+G26+L26 | N26: =Paramètres!$B$6 | O26: =ROUND(M26*N26,2) | P26: =O26*E26 | Q26: =M26*E26 | R26: Serveur Navori QL sur site 1 100 € (ESTIMATIF, non chiffré Sonepar) | S26: Paramétrage 16 lecteurs, groupes, alerte ; BE charte + 10 modèles FR/EN, formation
A27: 37 | B27: 4 | C27: Fourniture, pose et raccordement répartiteur informatique principal dans poste énergie Hub 3, incluant switch PoE | D27: Ens | E27: 1 | F27: 634.85 | G27: 0 | H27: 0 | I27: 5 | J27: 0 | K27: 0 | L27: =H27*Paramètres!$B$2+I27*Paramètres!$B$3+J27*Paramètres!$B$4+K27*Paramètres!$B$5 | M27: =F27+G27+L27 | N27: =Paramètres!$B$6 | O27: =ROUND(M27*N27,2) | P27: =O27*E27 | Q27: =M27*E27 | R27: Octet Plus DE044128 du 15/10/2026 : baie 42U + bandeau ; switch EXYTE | S27: Pose baie + switch
A28: 38 | B28: 4 | C28: Fourniture, pose et raccordement fibre OS2 12 brins depuis répartiteur principal poste énergie Hub 1 vers répartiteur principal poste énergie Hub 3 | D28: Ens | E28: 1 | F28: 753.92 | G28: 0 | H28: 3.75 | I28: 0 | J28: 0 | K28: 0 | L28: =H28*Paramètres!$B$2+I28*Paramètres!$B$3+J28*Paramètres!$B$4+K28*Paramètres!$B$5 | M28: =F28+G28+L28 | N28: =Paramètres!$B$6 | O28: =ROUND(M28*N28,2) | P28: =O28*E28 | Q28: =M28*E28 | R28: Octet Plus DE044128 du 15/10/2026 : OS2 ≈150 ml + tronçon | S28: Tirage 150 ml
A29: 39 | B29: 4 | C29: Fourniture, pose et raccordement fibre OS2 12 brins depuis répartiteur principal poste énergie Hub 3 vers répartiteurs secondaires A (Ilots 1 à 10) | D29: Ens | E29: 1 | F29: 818.2 | G29: 0 | H29: 5 | I29: 0 | J29: 0 | K29: 0 | L29: =H29*Paramètres!$B$2+I29*Paramètres!$B$3+J29*Paramètres!$B$4+K29*Paramètres!$B$5 | M29: =F29+G29+L29 | N29: =Paramètres!$B$6 | O29: =ROUND(M29*N29,2) | P29: =O29*E29 | Q29: =M29*E29 | R29: Octet Plus DE044128 du 15/10/2026 : OS2 ≈200 ml + tronçon | S29: Tirage 200 ml
... A36: 47 | B36: 4 | C36: Recettage cuivre | D36: Ens | E36: 1 | F36: 0 | G36: 0 | H36: 0 | I36: 38 | J36: 0 | K36: 0 | L36: =H36*Paramètres!$B$2+I36*Paramètres!$B$3+J36*Paramètres!$B$4+K36*Paramètres!$B$5 | M36: =F36+G36+L36 | N36: =Paramètres!$B$6 | O36: =ROUND(M36*N36,2) | P36: =O36*E36 | Q36: =M36*E36 | R36: Certification PROSYB | S36: 360 × 0,1 h + rapports
A37: 52 | B37: 5 | C37: Fourniture, pose et raccordement coffret report de contact SSI poste de garde principal | D37: Ens | E37: 1 | F37: 0 | G37: 1900 | H37: 0 | I37: 0 | J37: 4 | K37: 0 | L37: =H37*Paramètres!$B$2+I37*Paramètres!$B$3+J37*Paramètres!$B$4+K37*Paramètres!$B$5 | M37: =F37+G37+L37 | N37: =Paramètres!$B$7 | O37: =ROUND(M37*N37,2) | P37: =O37*E37 | Q37: =M37*E37 | R37: Coffret reports ≈30 contacts type SREI CA32 1 900 € (ESTIMATIF, acceptation report SSI à valider) | S37: Pose + câblage interne 4 h
A38: 53 | B38: 5 | C38: Fourniture, pose et raccordement liaisons coffret report de contact SSI vers alarmes BAAS SSI îlots 1 et 2, poste de garde, poste énergie Hub 1 | D38: Ens | E38: 1 | F38: 0 | G38: 3948 | H38: 32.4 | I38: 0 | J38: 5 | K38: 0 | L38: =H38*Paramètres!$B$2+I38*Paramètres!$B$3+J38*Paramètres!$B$4+K38*Paramètres!$B$5 | M38: =F38+G38+L38 | N38: =Paramètres!$B$7 | O38: =ROUND(M38*N38,2) | P38: =O38*E38 | Q38: =M38*E38 | R38: CR1-C1 5G1,5 / 7G1,5 (ESTIMATIF, consultation câbles L19 en cours) | S38: Tirage 1 080 m à 3 h/100 m + 5 raccordements
A39: 54 | B39: 5 | C39: Fourniture, pose et raccordement centrale type 3 SSI poste de garde, y compris déclencheurs manuels et sirenes | D39: Ens | E39: 1 | F39: 327.4 | G39: 0 | H39: 0 | I39: 0 | J39: 4 | K39: 0 | L39: =H39*Paramètres!$B$2+I39*Paramètres!$B$3+J39*Paramètres!$B$4+K39*Paramètres!$B$5 | M39: =F39+G39+L39 | N39: =Paramètres!$B$7 | O39: =ROUND(M39*N39,2) | P39: =O39*E39 | Q39: =M39*E39 | R39: AVISS AE2610CO901 v2 du 13/10/2026 : CONCEPT 3 177 + DM 4710R1 23,40 + capot 4 + TMS-300 98 + port 25 | S39: Pose + câblage 4 h
A40: 55 | B40: 5 | C40: Fourniture, pose et raccordement centrale type 3 SSI Poste Energie Hub 1, y compris déclencheurs manuels et sirenes | D40: Ens | E40: 1 | F40: 302.4 | G40: 0 | H40: 0 | I40: 0 | J40: 4 | K40: 0 | L40: =H40*Paramètres!$B$2+I40*Paramètres!$B$3+J40*Paramètres!$B$4+K40*Paramètres!$B$5 | M40: =F40+G40+L40 | N40: =Paramètres!$B$7 | O40: =ROUND(M40*N40,2) | P40: =O40*E40 | Q40: =M40*E40 | R40: AVISS AE2610CO901 v2 du 13/10/2026 : CONCEPT 3 + DM + capot + TMS-300 | S40: Idem
A41: 56 | B41: 5 | C41: Fourniture, pose et raccordement centrale type 3 SSI Poste Energie Hub 2, y compris déclencheurs manuels et sirenes | D41: Ens | E41: 1 | F41: 357.2 | G41: 0 | H41: 0 | I41: 0 | J41: 5 | K41: 0 | L41: =H41*Paramètres!$B$2+I41*Paramètres!$B$3+J41*Paramètres!$B$4+K41*Paramètres!$B$5 | M41: =F41+G41+L41 | N41: =Paramètres!$B$7 | O41: =ROUND(M41*N41,2) | P41: =O41*E41 | Q41: =M41*E41 | R41: AVISS AE2610CO901 v2 du 13/10/2026 : CONCEPT 3 + 3 DM + 3 capots + TMS-300 | S41: Idem + 2 DM
A42: 58 | B42: 5 | C42: Fourniture, pose et raccordement déclencheurs manuels chantier | D42: Ens | E42: 1 | F42: 1376 | G42: 1792 | H42: 54.4 | I42: 0 | J42: 8 | K42: 0 | L42: =H42*Paramètres!$B$2+I42*Paramètres!$B$3+J42*Paramètres!$B$4+K42*Paramètres!$B$5 | M42: =F42+G42+L42 | N42: =Paramètres!$B$7 | O42: =ROUND(M42*N42,2) | P42: =O42*E42 | Q42: =M42*E42 | R42: AVISS AE2610CO901 v2 du 13/10/2026 : 16 DM étanches IP65 4713R1C à 86 € ; câble CR1-C1 2×1,5 ESTIMATIF | S42: Tirage 1 280 m + pose 1 h/DM + racc. 0,5 h
A43: 59 | B43: 5 | C43: Fourniture, pose et raccordement diffuseurs sonores chantier | D43: Ens | E43: 1 | F43: 2124 | G43: 1824 | H43: 40.8 | I43: 0 | J43: 6 | K43: 0 | L43: =H43*Paramètres!$B$2+I43*Paramètres!$B$3+J43*Paramètres!$B$4+K43*Paramètres!$B$5 | M43: =F43+G43+L43 | N43: =Paramètres!$B$7 | O43: =ROUND(M43*N43,2) | P43: =O43*E43 | Q43: =M43*E43 | R43: AVISS AE2610CO901 v2 du 13/10/2026 : 12 CONCEPT 3 (IP45, pose sous abri) à 177 € ; câble CR1-C1 3G1,5 ESTIMATIF | S43: Tirage 960 m + pose + racc.
A44: 60 | B44: 5 | C44: Paramétrage et mise en service | D44: Ens | E44: 1 | F44: 0 | G44: 0 | H44: 0 | I44: 0 | J44: 8 | K44: 8 | L44: =H44*Paramètres!$B$2+I44*Paramètres!$B$3+J44*Paramètres!$B$4+K44*Paramètres!$B$5 | M44: =F44+G44+L44 | N44: =Paramètres!$B$7 | O44: =ROUND(M44*N44,2) | P44: =O44*E44 | Q44: =M44*E44 | R44: MO PROSYB | S44: Programmation, essais, PV ; BE synoptique, DOE
A45: 62 | B45: 5 | C45: Fourniture, pose et raccordement liaisons coffret report de contact SSI vers centrales SSI îlots 3 à 10 | D45: Ens | E45: 1 | F45: 0 | G45: 5800 | H45: 60 | I45: 0 | J45: 8 | K45: 0 | L45: =H45*Paramètres!$B$2+I45*Paramètres!$B$3+J45*Paramètres!$B$4+K45*Paramètres!$B$5 | M45: =F45+G45+L45 | N45: =Paramètres!$B$7 | O45: =ROUND(M45*N45,2) | P45: =O45*E45 | Q45: =M45*E45 | R45: CR1-C1 5G1,5 ≈2 000 m (ESTIMATIF) | S45: Tirage 3 h/100 m + 8 raccordements
A46: 64 | B46: 5 | C46: Paramétrage et mise en service | D46: Ens | E46: 1 | F46: 0 | G46: 0 | H46: 0 | I46: 0 | J46: 6 | K46: 2 | L46: =H46*Paramètres!$B$2+I46*Paramètres!$B$3+J46*Paramètres!$B$4+K46*Paramètres!$B$5 | M46: =F46+G46+L46 | N46: =Paramètres!$B$7 | O46: =ROUND(M46*N46,2) | P46: =O46*E46 | Q46: =M46*E46 | R46: MO PROSYB | S46: Essais reports îlots 3-10
A47: 66 | B47: 5 | C47: Fourniture, pose et raccordement centrale type 3 SSI Poste Energie Hub 3, y compris déclencheurs manuels et sirenes | D47: Ens | E47: 1 | F47: 302.4 | G47: 0 | H47: 0 | I47: 0 | J47: 4 | K47: 0 | L47: =H47*Paramètres!$B$2+I47*Paramètres!$B$3+J47*Paramètres!$B$4+K47*Paramètres!$B$5 | M47: =F47+G47+L47 | N47: =Paramètres!$B$7 | O47: =ROUND(M47*N47,2) | P47: =O47*E47 | Q47: =M47*E47 | R47: AVISS AE2610CO901 v2 du 13/10/2026 : CONCEPT 3 + DM + capot + TMS-300 | S47: Pose Hub 3
A48: 67 | B48: 5 | C48: Fourniture, pose et raccordement liaisons coffret report de contact SSI vers alarmes Type 3 SSI îlots 1 à 20, poste énergie Hub 3 | D48: Ens | E48: 1 | F48: 0 | G48: 9050 | H48: 75 | I48: 0 | J48: 20 | K48: 0 | L48: =H48*Paramètres!$B$2+I48*Paramètres!$B$3+J48*Paramètres!$B$4+K48*Paramètres!$B$5 | M48: =F48+G48+L48 | N48: =Paramètres!$B$7 | O48: =ROUND(M48*N48,2) | P48: =O48*E48 | Q48: =M48*E48 | R48: CR1-C1 7G1,5 / 5G1,5 ≈2 500 m (ESTIMATIF) | S48: Tirage + 20 raccordements
...

Sheet Points ouverts
A1: # | B1: Sujet | C1: Action | D1: Impact prix
A2: 1 | B2: GTB | C2: TMA, licence CARE et abonnement 5G AETHERYS sur 24 mois alors que chantier 29 mois (maintenance DPGF 28 mois) | D2: Demander à AETHERYS +5 mois ; provision 870 € PR intégrée | E2: +
A3: 2 | B3: GTB | C3: Connecteur RS485 750-960 cité dans le mémoire AETHERYS mais absent de son DPGF ; 3e bloc libellé « TGBT HUB 2 » au lieu de HUB 3 et « coupleur de bus » au lieu de PFC100 | D3: Faire corriger l'offre AETHERYS | E3: faible
A4: 3 | B4: GTB | C4: Alertes SMS : non décrites par AETHERYS (Ignition Edge = e-mail natif) alors que DPGF demande SMS/mail | D4: Confirmer passerelle SMS (IXON ou module Ignition) ou retirer SMS | E4: +250 € si passerelle
A5: 4 | B5: GTB | C5: Routeur IXON 5G = sortie internet du réseau terrain : contradiction avec « aucun accès internet direct » du mémoire | D5: Placer en VLAN 910 VPN de maintenance, activation sur validation EXYTE | E5: 0
A6: 5 | B6: Vidéo | C6: Caméras DS-2CD1643G2-LIZSU : fiche = détection de mouvement humain/véhicule seulement (pas de franchissement de ligne/intrusion de zone listés) ; NVR : protection périmétrique limitée à 2 voies 4 MP ; port des EPI non supporté | D6: Demander à CCF variante AcuSense (ex. gamme 2xx6G2-I…SU/SL) ou reformuler l'offre | E6: + à chiffrer
A7: 6 | B7: Vidéo | C7: NVR DS-7732NXI-K4 : 16 To max par disque selon fiche ; disque 20 To proposé + disque unique = point unique de panne | D7: Remplacer par 2 × 10 To (ou 4 × 8 To) compatibles | E7: ≈ neutre
A8: 7 | B8: AV | C8: Micro LOG025 MeetUp incompatible Rally Bar → 4 Rally Mic Pod 989-000430 ; chariot Chief 50-85" vs écran 86" ; totems ERARD prévus OH55F (portrait) vs OHDX | D8: Recotation Sonepar attendue | E8: ±
A9: 8 | B9: AV | C9: Serveur Navori QL et durée licence Navori non chiffrés | D9: Prix Sonepar | E9: 1 100 € estimatif
A10: 9 | B10: VDI | C10: Pose cuivre et certification classe EA non incluses Octet Plus ; coffrets IP55 retirés (SPIE) → devis révisé à demander | D10: Devis révisé Octet Plus | E10: 0
A11: 10 | B11: SSI | C11: Câbles CR1-C1, coffret de reports : prix de repli estimatifs | D11: Consultation L19 Sonepar en cours | E11: ±
A12: 11 | B12: Validité | C12: Devis fournisseurs valables 27-31/10/2026 alors que Haskoning exige ≥ 90 jours de validité | D12: Demander prolongation ou clause de révision | E12: risque
